Workbook

Sheet Read Me
B2: Daily Gamba — Acquisition CRM (Yuri)
B3: Same structure used company-wide - every rep gets their own copy of this file.
B6: What's in this file
B7: Yuri - Book | C7: — His full player database. Every player he owns, one row each. Status drives everything else automatically.
B8: Yuri - Daily Task | C8: — Auto-generated: exactly who he needs to contact today. Sorted by whoever he has gone longest without talking to - that player is always row 1. He works this top to bottom, no interpretation needed.
B9: Yuri - Stats | C9: — His personal scoreboard: total list vs. active list, VIP transfers, wager, and today's Active Leads/VIP Transfers/FTD vs. target.
B10: Team & KPI Targets | C10: — His daily KPI targets (editable).
B12: How the automation works
B13: Status (dropdown) | C13: — He sets this per player: Initial Contact -> Interested -> VIP Transferred -> KYC Complete -> First Deposit -> Active. Or Reactivation Queue / Dead Lead if they go cold. This is the main funnel and is independent from the VIP Team column below.
B14: Transferred to VIP Team (dropdown, Book tab only) | C14: — Separate from Status. Yes / No. Marks whether a player has been handed off to the in-house VIP team - can happen while Status stays Active (or anything else), since the two track different things at the same time. Setting it to Yes quietly starts a Day 1/7/14 check-in cadence behind the scenes (no extra columns to manage) which stops automatically after the 3rd check-in.
B15: Health (Book tab only) | C15: — A glance indicator, not what decides order. Yellow = early funnel, in progress. Green = converted and paying (First Deposit / Active). Red = overdue on follow-up, or Reactivation Queue. Black = dead lead. The Daily Task tab ignores this and sorts by most overdue instead - simpler and no colors to interpret.
B16: Next Action | C16: — Auto-calculated from Status. Tells him exactly what to do, no guessing.
B17: Next Follow-Up Date | C17: — Auto-calculated from Status + Last Contact Date, using the Day 0/1/3/7/14/30 cadence.
B18: Daily Task tab | C18: — Pulls in anyone whose Next Follow-Up Date is today or earlier, plus anyone who still has no Roobet Username (the #1 blocker to fix) - those clear once he's contacted them today, then come right back tomorrow if still no sign-up. Sorted with the longest-neglected player first.
B19: Follow-Up Attempts (Book tab) | C19: — Counts how many follow-ups he's logged on a player who still hasn't signed up for Roobet. At 3 attempts, Next Action flags "READY FOR DEAD LEAD" as a prompt - marking the Status is still his call. Resets to 0 automatically once they sign up.
B20: Dead Lead Reactivation (2nd block on Daily Task) | C20: — Every Dead Lead shows up here right away, ranked by Next Retarget Date (soonest first). A row only turns red once that date actually arrives (~30 days after last contact) - that's the signal to act. Kept separate from the main queue so dead leads never bury a fresh, hot lead.
B21: VIP Team check-ins | C21: — Once he sets Transferred to VIP Team to "Yes," he gets a Day 1/7/14 check-in prompt (did they deposit, are they active with the VIP team, do they need help). Stops automatically after the 3rd check-in - nothing to remember to switch off. Daily Task surfaces the player whenever either this cadence or their normal Status cadence is due.
B23: Two things formulas can't do (need one small script)
B24: Date Assigned | C24: — Ideally freezes automatically the moment a new player is added. In this pilot it's a manual date entry; I've got an Apps Script ready that automates it once we lock the structure.
B25: Last Contact Date | C25: — Ideally auto-updates when he checks a player off the Daily Task list. Same story - manual for now, automatable with the same script.
B27: Next step
B28: Adding this rep to the Master Dashboard | C28: — Once this file is a real Google Sheet and shared with Claude, send the Sheet URL and it gets added to the company-wide Master Dashboard automatically - no other changes needed.

Sheet Team & KPI Targets
A1: Daily KPI Targets
A2: Blue cells are editable inputs. This is the official 4-metric KPI framework - everything else (Follow-Ups, KYC Completed, etc.) is tracked internally on the Stats tab but isn't a formal target here. This tab is personal to this file only - other reps' targets live in their own files, not here.
A4: Name | B4: Role | C4: Platforms | D4: Daily Outreach (static, not tracked) | E4: Active Leads Target (must log) | F4: VIP Transfers Target | G4: Daily FTD Target
A5: Yuri | B5: Acquisition | C5: Discord, Telegram, Twitter, Instagram | D5: 100 | E5: 20 | F5: 3 | G5: 1

Sheet Lists
A1: Reps | B1: SourceChannels | C1: Status | D1: NextAction | E1: OffsetDays
A2: Yuri | B2: Instagram | C2: Initial Contact | D2: Day 1: Check Account, Check KYC, Help Deposit | E2: 1
A3: Tuna | B3: Discord | C3: Interested | D3: Check Account, Check KYC, Help Deposit | E3: 1
A4: Plat | B4: Twitter | C4: VIP Transferred | D4: Day 1 / Day 2 / Day 3 check-ins - urgent, help them finish KYC and lock in their first deposit. 3 attempts with still no deposit -> auto Dead Lead. | E4: 1/2/3
A5: Chella | B5: Telegram | C5: KYC Complete | D5: Help Deposit / Confirm Deposit Pending | E5: 1
A6: Moneyheist | B6: SlotEssentials | C6: First Deposit | D6: Day 3: Confirm Playing, Resolve Issues | E6: 3
A7: Seb | B7: Other | C7: Active | D7: Actively playing - check in periodically, encourage continued play. Hand to the VIP Team (separate column) when warranted, or move to Reactivation Queue if they go quiet. | E7: 14
A8: Jordan | C8: Reactivation Queue | D8: Reactivation outreach - win them back | E8: 3
A9: Seanok | C9: Dead Lead | D9: Re-target (every ~30 days): reach back out, see if anything changed. Update status if it goes anywhere. | E9: 30
A10: Prime | C10: Potential Lead | D10: Re-target (every 7 days): reach back out, see if they're ready to pick things back up. | E10: 7
A11: Daily
A12: Gwen
A13: Miko
A14: Concept

Sheet Yuri - Daily Task
A1: Yuri's Daily Task Queue
A2: Auto-pulled from his Book. Anyone overdue or due today, ranked. Work top to bottom - no thinking, just execute.
A4: Task Complete | B4: Match Row | C4: Player ID | D4: Player Name | E4: Due Date | F4: Owner | G4: Source | H4: Roobet Username | I4: Status (pick to update) | J4: Health | K4: Required Action | L4: Days Since Last Contact | M4: Notes
A5: FALSE | B5: =IFERROR(MATCH(1,'Yuri - Book'!$S$4:$S$203,0)+4-1,"") | C5: =IF($B5="","",INDEX('Yuri - Book'!$A:$A,$B5)) | D5: =IF($B5="","",INDEX('Yuri - Book'!$B:$B,$B5)) | E5: =IF($B5="","",INDEX('Yuri - Book'!$J:$J,$B5)) | F5: =IF($B5="","","Yuri") | G5: =IF($B5="","",INDEX('Yuri - Book'!$C:$C,$B5)) | H5: =IF($B5="","",INDEX('Yuri - Book'!$D:$D,$B5)) | I5: =IF($B5="","",INDEX('Yuri - Book'!$E:$E,$B5)) | J5: =IF($B5="","",INDEX('Yuri - Book'!$F:$F,$B5)) | K5: =IF($B5="","",INDEX('Yuri - Book'!$K:$K,$B5)) | L5: =IF($B5="","",ROUND(INDEX('Yuri - Book'!$Q:$Q,$B5),0)) | M5: =IF($B5="","",INDEX('Yuri - Book'!$P:$P,$B5))
A6: FALSE | B6: =IFERROR(MATCH(2,'Yuri - Book'!$S$4:$S$203,0)+4-1,"") | C6: =IF($B6="","",INDEX('Yuri - Book'!$A:$A,$B6)) | D6: =IF($B6="","",INDEX('Yuri - Book'!$B:$B,$B6)) | E6: =IF($B6="","",INDEX('Yuri - Book'!$J:$J,$B6)) | F6: =IF($B6="","","Yuri") | G6: =IF($B6="","",INDEX('Yuri - Book'!$C:$C,$B6)) | H6: =IF($B6="","",INDEX('Yuri - Book'!$D:$D,$B6)) | I6: =IF($B6="","",INDEX('Yuri - Book'!$E:$E,$B6)) | J6: =IF($B6="","",INDEX('Yuri - Book'!$F:$F,$B6)) | K6: =IF($B6="","",INDEX('Yuri - Book'!$K:$K,$B6)) | L6: =IF($B6="","",ROUND(INDEX('Yuri - Book'!$Q:$Q,$B6),0)) | M6: =IF($B6="","",INDEX('Yuri - Book'!$P:$P,$B6))
A7: FALSE | B7: =IFERROR(MATCH(3,'Yuri - Book'!$S$4:$S$203,0)+4-1,"") | C7: =IF($B7="","",INDEX('Yuri - Book'!$A:$A,$B7)) | D7: =IF($B7="","",INDEX('Yuri - Book'!$B:$B,$B7)) | E7: =IF($B7="","",INDEX('Yuri - Book'!$J:$J,$B7)) | F7: =IF($B7="","","Yuri") | G7: =IF($B7="","",INDEX('Yuri - Book'!$C:$C,$B7)) | H7: =IF($B7="","",INDEX('Yuri - Book'!$D:$D,$B7)) | I7: =IF($B7="","",INDEX('Yuri - Book'!$E:$E,$B7)) | J7: =IF($B7="","",INDEX('Yuri - Book'!$F:$F,$B7)) | K7: =IF($B7="","",INDEX('Yuri - Book'!$K:$K,$B7)) | L7: =IF($B7="","",ROUND(INDEX('Yuri - Book'!$Q:$Q,$B7),0)) | M7: =IF($B7="","",INDEX('Yuri - Book'!$P:$P,$B7))
A8: FALSE | B8: =IFERROR(MATCH(4,'Yuri - Book'!$S$4:$S$203,0)+4-1,"") | C8: =IF($B8="","",INDEX('Yuri - Book'!$A:$A,$B8)) | D8: =IF($B8="","",INDEX('Yuri - Book'!$B:$B,$B8)) | E8: =IF($B8="","",INDEX('Yuri - Book'!$J:$J,$B8)) | F8: =IF($B8="","","Yuri") | G8: =IF($B8="","",INDEX('Yuri - Book'!$C:$C,$B8)) | H8: =IF($B8="","",INDEX('Yuri - Book'!$D:$D,$B8)) | I8: =IF($B8="","",INDEX('Yuri - Book'!$E:$E,$B8)) | J8: =IF($B8="","",INDEX('Yuri - Book'!$F:$F,$B8)) | K8: =IF($B8="","",INDEX('Yuri - Book'!$K:$K,$B8)) | L8: =IF($B8="","",ROUND(INDEX('Yuri - Book'!$Q:$Q,$B8),0)) | M8: =IF($B8="","",INDEX('Yuri - Book'!$P:$P,$B8))
A9: FALSE | B9: =IFERROR(MATCH(5,'Yuri - Book'!$S$4:$S$203,0)+4-1,"") | C9: =IF($B9="","",INDEX('Yuri - Book'!$A:$A,$B9)) | D9: =IF($B9="","",INDEX('Yuri - Book'!$B:$B,$B9)) | E9: =IF($B9="","",INDEX('Yuri - Book'!$J:$J,$B9)) | F9: =IF($B9="","","Yuri") | G9: =IF($B9="","",INDEX('Yuri - Book'!$C:$C,$B9)) | H9: =IF($B9="","",INDEX('Yuri - Book'!$D:$D,$B9)) | I9: =IF($B9="","",INDEX('Yuri - Book'!$E:$E,$B9)) | J9: =IF($B9="","",INDEX('Yuri - Book'!$F:$F,$B9)) | K9: =IF($B9="","",INDEX('Yuri - Book'!$K:$K,$B9)) | L9: =IF($B9="","",ROUND(INDEX('Yuri - Book'!$Q:$Q,$B9),0)) | M9: =IF($B9="","",INDEX('Yuri - Book'!$P:$P,$B9))
A10: FALSE | B10: =IFERROR(MATCH(6,'Yuri - Book'!$S$4:$S$203,0)+4-1,"") | C10: =IF($B10="","",INDEX('Yuri - Book'!$A:$A,$B10)) | D10: =IF($B10="","",INDEX('Yuri - Book'!$B:$B,$B10)) | E10: =IF($B10="","",INDEX('Yuri - Book'!$J:$J,$B10)) | F10: =IF($B10="","","Yuri") | G10: =IF($B10="","",INDEX('Yuri - Book'!$C:$C,$B10)) | H10: =IF($B10="","",INDEX('Yuri - Book'!$D:$D,$B10)) | I10: =IF($B10="","",INDEX('Yuri - Book'!$E:$E,$B10)) | J10: =IF($B10="","",INDEX('Yuri - Book'!$F:$F,$B10)) | K10: =IF($B10="","",INDEX('Yuri - Book'!$K:$K,$B10)) | L10: =IF($B10="","",ROUND(INDEX('Yuri - Book'!$Q:$Q,$B10),0)) | M10: =IF($B10="","",INDEX('Yuri - Book'!$P:$P,$B10))
A11: FALSE | B11: =IFERROR(MATCH(7,'Yuri - Book'!$S$4:$S$203,0)+4-1,"") | C11: =IF($B11="","",INDEX('Yuri - Book'!$A:$A,$B11)) | D11: =IF($B11="","",INDEX('Yuri - Book'!$B:$B,$B11)) | E11: =IF($B11="","",INDEX('Yuri - Book'!$J:$J,$B11)) | F11: =IF($B11="","","Yuri") | G11: =IF($B11="","",INDEX('Yuri - Book'!$C:$C,$B11)) | H11: =IF($B11="","",INDEX('Yuri - Book'!$D:$D,$B11)) | I11: =IF($B11="","",INDEX('Yuri - Book'!$E:$E,$B11)) | J11: =IF($B11="","",INDEX('Yuri - Book'!$F:$F,$B11)) | K11: =IF($B11="","",INDEX('Yuri - Book'!$K:$K,$B11)) | L11: =IF($B11="","",ROUND(INDEX('Yuri - Book'!$Q:$Q,$B11),0)) | M11: =IF($B11="","",INDEX('Yuri - Book'!$P:$P,$B11))
A12: FALSE | B12: =IFERROR(MATCH(8,'Yuri - Book'!$S$4:$S$203,0)+4-1,"") | C12: =IF($B12="","",INDEX('Yuri - Book'!$A:$A,$B12)) | D12: =IF($B12="","",INDEX('Yuri - Book'!$B:$B,$B12)) | E12: =IF($B12="","",INDEX('Yuri - Book'!$J:$J,$B12)) | F12: =IF($B12="","","Yuri") | G12: =IF($B12="","",INDEX('Yuri - Book'!$C:$C,$B12)) | H12: =IF($B12="","",INDEX('Yuri - Book'!$D:$D,$B12)) | I12: =IF($B12="","",INDEX('Yuri - Book'!$E:$E,$B12)) | J12: =IF($B12="","",INDEX('Yuri - Book'!$F:$F,$B12)) | K12: =IF($B12="","",INDEX('Yuri - Book'!$K:$K,$B12)) | L12: =IF($B12="","",ROUND(INDEX('Yuri - Book'!$Q:$Q,$B12),0)) | M12: =IF($B12="","",INDEX('Yuri - Book'!$P:$P,$B12))
A13: FALSE | B13: =IFERROR(MATCH(9,'Yuri - Book'!$S$4:$S$203,0)+4-1,"") | C13: =IF($B13="","",INDEX('Yuri - Book'!$A:$A,$B13)) | D13: =IF($B13="","",INDEX('Yuri - Book'!$B:$B,$B13)) | E13: =IF($B13="","",INDEX('Yuri - Book'!$J:$J,$B13)) | F13: =IF($B13="","","Yuri") | G13: =IF($B13="","",INDEX('Yuri - Book'!$C:$C,$B13)) | H13: =IF($B13="","",INDEX('Yuri - Book'!$D:$D,$B13)) | I13: =IF($B13="","",INDEX('Yuri - Book'!$E:$E,$B13)) | J13: =IF($B13="","",INDEX('Yuri - Book'!$F:$F,$B13)) | K13: =IF($B13="","",INDEX('Yuri - Book'!$K:$K,$B13)) | L13: =IF($B13="","",ROUND(INDEX('Yuri - Book'!$Q:$Q,$B13),0)) | M13: =IF($B13="","",INDEX('Yuri - Book'!$P:$P,$B13))
A14: FALSE | B14: =IFERROR(MATCH(10,'Yuri - Book'!$S$4:$S$203,0)+4-1,"") | C14: =IF($B14="","",INDEX('Yuri - Book'!$A:$A,$B14)) | D14: =IF($B14="","",INDEX('Yuri - Book'!$B:$B,$B14)) | E14: =IF($B14="","",INDEX('Yuri - Book'!$J:$J,$B14)) | F14: =IF($B14="","","Yuri") | G14: =IF($B14="","",INDEX('Yuri - Book'!$C:$C,$B14)) | H14: =IF($B14="","",INDEX('Yuri - Book'!$D:$D,$B14)) | I14: =IF($B14="","",INDEX('Yuri - Book'!$E:$E,$B14)) | J14: =IF($B14="","",INDEX('Yuri - Book'!$F:$F,$B14)) | K14: =IF($B14="","",INDEX('Yuri - Book'!$K:$K,$B14)) | L14: =IF($B14="","",ROUND(INDEX('Yuri - Book'!$Q:$Q,$B14),0)) | M14: =IF($B14="","",INDEX('Yuri - Book'!$P:$P,$B14))
A15: FALSE | B15: =IFERROR(MATCH(11,'Yuri - Book'!$S$4:$S$203,0)+4-1,"") | C15: =IF($B15="","",INDEX('Yuri - Book'!$A:$A,$B15)) | D15: =IF($B15="","",INDEX('Yuri - Book'!$B:$B,$B15)) | E15: =IF($B15="","",INDEX('Yuri - Book'!$J:$J,$B15)) | F15: =IF($B15="","","Yuri") | G15: =IF($B15="","",INDEX('Yuri - Book'!$C:$C,$B15)) | H15: =IF($B15="","",INDEX('Yuri - Book'!$D:$D,$B15)) | I15: =IF($B15="","",INDEX('Yuri - Book'!$E:$E,$B15)) | J15: =IF($B15="","",INDEX('Yuri - Book'!$F:$F,$B15)) | K15: =IF($B15="","",INDEX('Yuri - Book'!$K:$K,$B15)) | L15: =IF($B15="","",ROUND(INDEX('Yuri - Book'!$Q:$Q,$B15),0)) | M15: =IF($B15="","",INDEX('Yuri - Book'!$P:$P,$B15))
A16: FALSE | B16: =IFERROR(MATCH(12,'Yuri - Book'!$S$4:$S$203,0)+4-1,"") | C16: =IF($B16="","",INDEX('Yuri - Book'!$A:$A,$B16)) | D16: =IF($B16="","",INDEX('Yuri - Book'!$B:$B,$B16)) | E16: =IF($B16="","",INDEX('Yuri - Book'!$J:$J,$B16)) | F16: =IF($B16="","","Yuri") | G16: =IF($B16="","",INDEX('Yuri - Book'!$C:$C,$B16)) | H16: =IF($B16="","",INDEX('Yuri - Book'!$D:$D,$B16)) | I16: =IF($B16="","",INDEX('Yuri - Book'!$E:$E,$B16)) | J16: =IF($B16="","",INDEX('Yuri - Book'!$F:$F,$B16)) | K16: =IF($B16="","",INDEX('Yuri - Book'!$K:$K,$B16)) | L16: =IF($B16="","",ROUND(INDEX('Yuri - Book'!$Q:$Q,$B16),0)) | M16: =IF($B16="","",INDEX('Yuri - Book'!$P:$P,$B16))
A17: FALSE | B17: =IFERROR(MATCH(13,'Yuri - Book'!$S$4:$S$203,0)+4-1,"") | C17: =IF($B17="","",INDEX('Yuri - Book'!$A:$A,$B17)) | D17: =IF($B17="","",INDEX('Yuri - Book'!$B:$B,$B17)) | E17: =IF($B17="","",INDEX('Yuri - Book'!$J:$J,$B17)) | F17: =IF($B17="","","Yuri") | G17: =IF($B17="","",INDEX('Yuri - Book'!$C:$C,$B17)) | H17: =IF($B17="","",INDEX('Yuri - Book'!$D:$D,$B17)) | I17: =IF($B17="","",INDEX('Yuri - Book'!$E:$E,$B17)) | J17: =IF($B17="","",INDEX('Yuri - Book'!$F:$F,$B17)) | K17: =IF($B17="","",INDEX('Yuri - Book'!$K:$K,$B17)) | L17: =IF($B17="","",ROUND(INDEX('Yuri - Book'!$Q:$Q,$B17),0)) | M17: =IF($B17="","",INDEX('Yuri - Book'!$P:$P,$B17))
A18: FALSE | B18: =IFERROR(MATCH(14,'Yuri - Book'!$S$4:$S$203,0)+4-1,"") | C18: =IF($B18="","",INDEX('Yuri - Book'!$A:$A,$B18)) | D18: =IF($B18="","",INDEX('Yuri - Book'!$B:$B,$B18)) | E18: =IF($B18="","",INDEX('Yuri - Book'!$J:$J,$B18)) | F18: =IF($B18="","","Yuri") | G18: =IF($B18="","",INDEX('Yuri - Book'!$C:$C,$B18)) | H18: =IF($B18="","",INDEX('Yuri - Book'!$D:$D,$B18)) | I18: =IF($B18="","",INDEX('Yuri - Book'!$E:$E,$B18)) | J18: =IF($B18="","",INDEX('Yuri - Book'!$F:$F,$B18)) | K18: =IF($B18="","",INDEX('Yuri - Book'!$K:$K,$B18)) | L18: =IF($B18="","",ROUND(INDEX('Yuri - Book'!$Q:$Q,$B18),0)) | M18: =IF($B18="","",INDEX('Yuri - Book'!$P:$P,$B18))
A19: FALSE | B19: =IFERROR(MATCH(15,'Yuri - Book'!$S$4:$S$203,0)+4-1,"") | C19: =IF($B19="","",INDEX('Yuri - Book'!$A:$A,$B19)) | D19: =IF($B19="","",INDEX('Yuri - Book'!$B:$B,$B19)) | E19: =IF($B19="","",INDEX('Yuri - Book'!$J:$J,$B19)) | F19: =IF($B19="","","Yuri") | G19: =IF($B19="","",INDEX('Yuri - Book'!$C:$C,$B19)) | H19: =IF($B19="","",INDEX('Yuri - Book'!$D:$D,$B19)) | I19: =IF($B19="","",INDEX('Yuri - Book'!$E:$E,$B19)) | J19: =IF($B19="","",INDEX('Yuri - Book'!$F:$F,$B19)) | K19: =IF($B19="","",INDEX('Yuri - Book'!$K:$K,$B19)) | L19: =IF($B19="","",ROUND(INDEX('Yuri - Book'!$Q:$Q,$B19),0)) | M19: =IF($B19="","",INDEX('Yuri - Book'!$P:$P,$B19))
A20: FALSE | B20: =IFERROR(MATCH(16,'Yuri - Book'!$S$4:$S$203,0)+4-1,"") | C20: =IF($B20="","",INDEX('Yuri - Book'!$A:$A,$B20)) | D20: =IF($B20="","",INDEX('Yuri - Book'!$B:$B,$B20)) | E20: =IF($B20="","",INDEX('Yuri - Book'!$J:$J,$B20)) | F20: =IF($B20="","","Yuri") | G20: =IF($B20="","",INDEX('Yuri - Book'!$C:$C,$B20)) | H20: =IF($B20="","",INDEX('Yuri - Book'!$D:$D,$B20)) | I20: =IF($B20="","",INDEX('Yuri - Book'!$E:$E,$B20)) | J20: =IF($B20="","",INDEX('Yuri - Book'!$F:$F,$B20)) | K20: =IF($B20="","",INDEX('Yuri - Book'!$K:$K,$B20)) | L20: =IF($B20="","",ROUND(INDEX('Yuri - Book'!$Q:$Q,$B20),0)) | M20: =IF($B20="","",INDEX('Yuri - Book'!$P:$P,$B20))
A21: FALSE | B21: =IFERROR(MATCH(17,'Yuri - Book'!$S$4:$S$203,0)+4-1,"") | C21: =IF($B21="","",INDEX('Yuri - Book'!$A:$A,$B21)) | D21: =IF($B21="","",INDEX('Yuri - Book'!$B:$B,$B21)) | E21: =IF($B21="","",INDEX('Yuri - Book'!$J:$J,$B21)) | F21: =IF($B21="","","Yuri") | G21: =IF($B21="","",INDEX('Yuri - Book'!$C:$C,$B21)) | H21: =IF($B21="","",INDEX('Yuri - Book'!$D:$D,$B21)) | I21: =IF($B21="","",INDEX('Yuri - Book'!$E:$E,$B21)) | J21: =IF($B21="","",INDEX('Yuri - Book'!$F:$F,$B21)) | K21: =IF($B21="","",INDEX('Yuri - Book'!$K:$K,$B21)) | L21: =IF($B21="","",ROUND(INDEX('Yuri - Book'!$Q:$Q,$B21),0)) | M21: =IF($B21="","",INDEX('Yuri - Book'!$P:$P,$B21))
A22: FALSE | B22: =IFERROR(MATCH(18,'Yuri - Book'!$S$4:$S$203,0)+4-1,"") | C22: =IF($B22="","",INDEX('Yuri - Book'!$A:$A,$B22)) | D22: =IF($B22="","",INDEX('Yuri - Book'!$B:$B,$B22)) | E22: =IF($B22="","",INDEX('Yuri - Book'!$J:$J,$B22)) | F22: =IF($B22="","","Yuri") | G22: =IF($B22="","",INDEX('Yuri - Book'!$C:$C,$B22)) | H22: =IF($B22="","",INDEX('Yuri - Book'!$D:$D,$B22)) | I22: =IF($B22="","",INDEX('Yuri - Book'!$E:$E,$B22)) | J22: =IF($B22="","",INDEX('Yuri - Book'!$F:$F,$B22)) | K22: =IF($B22="","",INDEX('Yuri - Book'!$K:$K,$B22)) | L22: =IF($B22="","",ROUND(INDEX('Yuri - Book'!$Q:$Q,$B22),0)) | M22: =IF($B22="","",INDEX('Yuri - Book'!$P:$P,$B22))
A23: FALSE | B23: =IFERROR(MATCH(19,'Yuri - Book'!$S$4:$S$203,0)+4-1,"") | C23: =IF($B23="","",INDEX('Yuri - Book'!$A:$A,$B23)) | D23: =IF($B23="","",INDEX('Yuri - Book'!$B:$B,$B23)) | E23: =IF($B23="","",INDEX('Yuri - Book'!$J:$J,$B23)) | F23: =IF($B23="","","Yuri") | G23: =IF($B23="","",INDEX('Yuri - Book'!$C:$C,$B23)) | H23: =IF($B23="","",INDEX('Yuri - Book'!$D:$D,$B23)) | I23: =IF($B23="","",INDEX('Yuri - Book'!$E:$E,$B23)) | J23: =IF($B23="","",INDEX('Yuri - Book'!$F:$F,$B23)) | K23: =IF($B23="","",INDEX('Yuri - Book'!$K:$K,$B23)) | L23: =IF($B23="","",ROUND(INDEX('Yuri - Book'!$Q:$Q,$B23),0)) | M23: =IF($B23="","",INDEX('Yuri - Book'!$P:$P,$B23))
A24: FALSE | B24: =IFERROR(MATCH(20,'Yuri - Book'!$S$4:$S$203,0)+4-1,"") | C24: =IF($B24="","",INDEX('Yuri - Book'!$A:$A,$B24)) | D24: =IF($B24="","",INDEX('Yuri - Book'!$B:$B,$B24)) | E24: =IF($B24="","",INDEX('Yuri - Book'!$J:$J,$B24)) | F24: =IF($B24="","","Yuri") | G24: =IF($B24="","",INDEX('Yuri - Book'!$C:$C,$B24)) | H24: =IF($B24="","",INDEX('Yuri - Book'!$D:$D,$B24)) | I24: =IF($B24="","",INDEX('Yuri - Book'!$E:$E,$B24)) | J24: =IF($B24="","",INDEX('Yuri - Book'!$F:$F,$B24)) | K24: =IF($B24="","",INDEX('Yuri - Book'!$K:$K,$B24)) | L24: =IF($B24="","",ROUND(INDEX('Yuri - Book'!$Q:$Q,$B24),0)) | M24: =IF($B24="","",INDEX('Yuri - Book'!$P:$P,$B24))
A25: FALSE | B25: =IFERROR(MATCH(21,'Yuri - Book'!$S$4:$S$203,0)+4-1,"") | C25: =IF($B25="","",INDEX('Yuri - Book'!$A:$A,$B25)) | D25: =IF($B25="","",INDEX('Yuri - Book'!$B:$B,$B25)) | E25: =IF($B25="","",INDEX('Yuri - Book'!$J:$J,$B25)) | F25: =IF($B25="","","Yuri") | G25: =IF($B25="","",INDEX('Yuri - Book'!$C:$C,$B25)) | H25: =IF($B25="","",INDEX('Yuri - Book'!$D:$D,$B25)) | I25: =IF($B25="","",INDEX('Yuri - Book'!$E:$E,$B25)) | J25: =IF($B25="","",INDEX('Yuri - Book'!$F:$F,$B25)) | K25: =IF($B25="","",INDEX('Yuri - Book'!$K:$K,$B25)) | L25: =IF($B25="","",ROUND(INDEX('Yuri - Book'!$Q:$Q,$B25),0)) | M25: =IF($B25="","",INDEX('Yuri - Book'!$P:$P,$B25))
A26: FALSE | B26: =IFERROR(MATCH(22,'Yuri - Book'!$S$4:$S$203,0)+4-1,"") | C26: =IF($B26="","",INDEX('Yuri - Book'!$A:$A,$B26)) | D26: =IF($B26="","",INDEX('Yuri - Book'!$B:$B,$B26)) | E26: =IF($B26="","",INDEX('Yuri - Book'!$J:$J,$B26)) | F26: =IF($B26="","","Yuri") | G26: =IF($B26="","",INDEX('Yuri - Book'!$C:$C,$B26)) | H26: =IF($B26="","",INDEX('Yuri - Book'!$D:$D,$B26)) | I26: =IF($B26="","",INDEX('Yuri - Book'!$E:$E,$B26)) | J26: =IF($B26="","",INDEX('Yuri - Book'!$F:$F,$B26)) | K26: =IF($B26="","",INDEX('Yuri - Book'!$K:$K,$B26)) | L26: =IF($B26="","",ROUND(INDEX('Yuri - Book'!$Q:$Q,$B26),0)) | M26: =IF($B26="","",INDEX('Yuri - Book'!$P:$P,$B26))
A27: FALSE | B27: =IFERROR(MATCH(23,'Yuri - Book'!$S$4:$S$203,0)+4-1,"") | C27: =IF($B27="","",INDEX('Yuri - Book'!$A:$A,$B27)) | D27: =IF($B27="","",INDEX('Yuri - Book'!$B:$B,$B27)) | E27: =IF($B27="","",INDEX('Yuri - Book'!$J:$J,$B27)) | F27: =IF($B27="","","Yuri") | G27: =IF($B27="","",INDEX('Yuri - Book'!$C:$C,$B27)) | H27: =IF($B27="","",INDEX('Yuri - Book'!$D:$D,$B27)) | I27: =IF($B27="","",INDEX('Yuri - Book'!$E:$E,$B27)) | J27: =IF($B27="","",INDEX('Yuri - Book'!$F:$F,$B27)) | K27: =IF($B27="","",INDEX('Yuri - Book'!$K:$K,$B27)) | L27: =IF($B27="","",ROUND(INDEX('Yuri - Book'!$Q:$Q,$B27),0)) | M27: =IF($B27="","",INDEX('Yuri - Book'!$P:$P,$B27))
A28: FALSE | B28: =IFERROR(MATCH(24,'Yuri - Book'!$S$4:$S$203,0)+4-1,"") | C28: =IF($B28="","",INDEX('Yuri - Book'!$A:$A,$B28)) | D28: =IF($B28="","",INDEX('Yuri - Book'!$B:$B,$B28)) | E28: =IF($B28="","",INDEX('Yuri - Book'!$J:$J,$B28)) | F28: =IF($B28="","","Yuri") | G28: =IF($B28="","",INDEX('Yuri - Book'!$C:$C,$B28)) | H28: =IF($B28="","",INDEX('Yuri - Book'!$D:$D,$B28)) | I28: =IF($B28="","",INDEX('Yuri - Book'!$E:$E,$B28)) | J28: =IF($B28="","",INDEX('Yuri - Book'!$F:$F,$B28)) | K28: =IF($B28="","",INDEX('Yuri - Book'!$K:$K,$B28)) | L28: =IF($B28="","",ROUND(INDEX('Yuri - Book'!$Q:$Q,$B28),0)) | M28: =IF($B28="","",INDEX('Yuri - Book'!$P:$P,$B28))
A29: FALSE | B29: =IFERROR(MATCH(25,'Yuri - Book'!$S$4:$S$203,0)+4-1,"") | C29: =IF($B29="","",INDEX('Yuri - Book'!$A:$A,$B29)) | D29: =IF($B29="","",INDEX('Yuri - Book'!$B:$B,$B29)) | E29: =IF($B29="","",INDEX('Yuri - Book'!$J:$J,$B29)) | F29: =IF($B29="","","Yuri") | G29: =IF($B29="","",INDEX('Yuri - Book'!$C:$C,$B29)) | H29: =IF($B29="","",INDEX('Yuri - Book'!$D:$D,$B29)) | I29: =IF($B29="","",INDEX('Yuri - Book'!$E:$E,$B29)) | J29: =IF($B29="","",INDEX('Yuri - Book'!$F:$F,$B29)) | K29: =IF($B29="","",INDEX('Yuri - Book'!$K:$K,$B29)) | L29: =IF($B29="","",ROUND(INDEX('Yuri - Book'!$Q:$Q,$B29),0)) | M29: =IF($B29="","",INDEX('Yuri - Book'!$P:$P,$B29))
A30: FALSE | B30: =IFERROR(MATCH(26,'Yuri - Book'!$S$4:$S$203,0)+4-1,"") | C30: =IF($B30="","",INDEX('Yuri - Book'!$A:$A,$B30)) | D30: =IF($B30="","",INDEX('Yuri - Book'!$B:$B,$B30)) | E30: =IF($B30="","",INDEX('Yuri - Book'!$J:$J,$B30)) | F30: =IF($B30="","","Yuri") | G30: =IF($B30="","",INDEX('Yuri - Book'!$C:$C,$B30)) | H30: =IF($B30="","",INDEX('Yuri - Book'!$D:$D,$B30)) | I30: =IF($B30="","",INDEX('Yuri - Book'!$E:$E,$B30)) | J30: =IF($B30="","",INDEX('Yuri - Book'!$F:$F,$B30)) | K30: =IF($B30="","",INDEX('Yuri - Book'!$K:$K,$B30)) | L30: =IF($B30="","",ROUND(INDEX('Yuri - Book'!$Q:$Q,$B30),0)) | M30: =IF($B30="","",INDEX('Yuri - Book'!$P:$P,$B30))
A31: FALSE | B31: =IFERROR(MATCH(27,'Yuri - Book'!$S$4:$S$203,0)+4-1,"") | C31: =IF($B31="","",INDEX('Yuri - Book'!$A:$A,$B31)) | D31: =IF($B31="","",INDEX('Yuri - Book'!$B:$B,$B31)) | E31: =IF($B31="","",INDEX('Yuri - Book'!$J:$J,$B31)) | F31: =IF($B31="","","Yuri") | G31: =IF($B31="","",INDEX('Yuri - Book'!$C:$C,$B31)) | H31: =IF($B31="","",INDEX('Yuri - Book'!$D:$D,$B31)) | I31: =IF($B31="","",INDEX('Yuri - Book'!$E:$E,$B31)) | J31: =IF($B31="","",INDEX('Yuri - Book'!$F:$F,$B31)) | K31: =IF($B31="","",INDEX('Yuri - Book'!$K:$K,$B31)) | L31: =IF($B31="","",ROUND(INDEX('Yuri - Book'!$Q:$Q,$B31),0)) | M31: =IF($B31="","",INDEX('Yuri - Book'!$P:$P,$B31))
A32: FALSE | B32: =IFERROR(MATCH(28,'Yuri - Book'!$S$4:$S$203,0)+4-1,"") | C32: =IF($B32="","",INDEX('Yuri - Book'!$A:$A,$B32)) | D32: =IF($B32="","",INDEX('Yuri - Book'!$B:$B,$B32)) | E32: =IF($B32="","",INDEX('Yuri - Book'!$J:$J,$B32)) | F32: =IF($B32="","","Yuri") | G32: =IF($B32="","",INDEX('Yuri - Book'!$C:$C,$B32)) | H32: =IF($B32="","",INDEX('Yuri - Book'!$D:$D,$B32)) | I32: =IF($B32="","",INDEX('Yuri - Book'!$E:$E,$B32)) | J32: =IF($B32="","",INDEX('Yuri - Book'!$F:$F,$B32)) | K32: =IF($B32="","",INDEX('Yuri - Book'!$K:$K,$B32)) | L32: =IF($B32="","",ROUND(INDEX('Yuri - Book'!$Q:$Q,$B32),0)) | M32: =IF($B32="","",INDEX('Yuri - Book'!$P:$P,$B32))
A33: FALSE | B33: =IFERROR(MATCH(29,'Yuri - Book'!$S$4:$S$203,0)+4-1,"") | C33: =IF($B33="","",INDEX('Yuri - Book'!$A:$A,$B33)) | D33: =IF($B33="","",INDEX('Yuri - Book'!$B:$B,$B33)) | E33: =IF($B33="","",INDEX('Yuri - Book'!$J:$J,$B33)) | F33: =IF($B33="","","Yuri") | G33: =IF($B33="","",INDEX('Yuri - Book'!$C:$C,$B33)) | H33: =IF($B33="","",INDEX('Yuri - Book'!$D:$D,$B33)) | I33: =IF($B33="","",INDEX('Yuri - Book'!$E:$E,$B33)) | J33: =IF($B33="","",INDEX('Yuri - Book'!$F:$F,$B33)) | K33: =IF($B33="","",INDEX('Yuri - Book'!$K:$K,$B33)) | L33: =IF($B33="","",ROUND(INDEX('Yuri - Book'!$Q:$Q,$B33),0)) | M33: =IF($B33="","",INDEX('Yuri - Book'!$P:$P,$B33))
A34: FALSE | B34: =IFERROR(MATCH(30,'Yuri - Book'!$S$4:$S$203,0)+4-1,"") | C34: =IF($B34="","",INDEX('Yuri - Book'!$A:$A,$B34)) | D34: =IF($B34="","",INDEX('Yuri - Book'!$B:$B,$B34)) | E34: =IF($B34="","",INDEX('Yuri - Book'!$J:$J,$B34)) | F34: =IF($B34="","","Yuri") | G34: =IF($B34="","",INDEX('Yuri - Book'!$C:$C,$B34)) | H34: =IF($B34="","",INDEX('Yuri - Book'!$D:$D,$B34)) | I34: =IF($B34="","",INDEX('Yuri - Book'!$E:$E,$B34)) | J34: =IF($B34="","",INDEX('Yuri - Book'!$F:$F,$B34)) | K34: =IF($B34="","",INDEX('Yuri - Book'!$K:$K,$B34)) | L34: =IF($B34="","",ROUND(INDEX('Yuri - Book'!$Q:$Q,$B34),0)) | M34: =IF($B34="","",INDEX('Yuri - Book'!$P:$P,$B34))
A35: FALSE | B35: =IFERROR(MATCH(31,'Yuri - Book'!$S$4:$S$203,0)+4-1,"") | C35: =IF($B35="","",INDEX('Yuri - Book'!$A:$A,$B35)) | D35: =IF($B35="","",INDEX('Yuri - Book'!$B:$B,$B35)) | E35: =IF($B35="","",INDEX('Yuri - Book'!$J:$J,$B35)) | F35: =IF($B35="","","Yuri") | G35: =IF($B35="","",INDEX('Yuri - Book'!$C:$C,$B35)) | H35: =IF($B35="","",INDEX('Yuri - Book'!$D:$D,$B35)) | I35: =IF($B35="","",INDEX('Yuri - Book'!$E:$E,$B35)) | J35: =IF($B35="","",INDEX('Yuri - Book'!$F:$F,$B35)) | K35: =IF($B35="","",INDEX('Yuri - Book'!$K:$K,$B35)) | L35: =IF($B35="","",ROUND(INDEX('Yuri - Book'!$Q:$Q,$B35),0)) | M35: =IF($B35="","",INDEX('Yuri - Book'!$P:$P,$B35))
A36: FALSE | B36: =IFERROR(MATCH(32,'Yuri - Book'!$S$4:$S$203,0)+4-1,"") | C36: =IF($B36="","",INDEX('Yuri - Book'!$A:$A,$B36)) | D36: =IF($B36="","",INDEX('Yuri - Book'!$B:$B,$B36)) | E36: =IF($B36="","",INDEX('Yuri - Book'!$J:$J,$B36)) | F36: =IF($B36="","","Yuri") | G36: =IF($B36="","",INDEX('Yuri - Book'!$C:$C,$B36)) | H36: =IF($B36="","",INDEX('Yuri - Book'!$D:$D,$B36)) | I36: =IF($B36="","",INDEX('Yuri - Book'!$E:$E,$B36)) | J36: =IF($B36="","",INDEX('Yuri - Book'!$F:$F,$B36)) | K36: =IF($B36="","",INDEX('Yuri - Book'!$K:$K,$B36)) | L36: =IF($B36="","",ROUND(INDEX('Yuri - Book'!$Q:$Q,$B36),0)) | M36: =IF($B36="","",INDEX('Yuri - Book'!$P:$P,$B36))
A37: FALSE | B37: =IFERROR(MATCH(33,'Yuri - Book'!$S$4:$S$203,0)+4-1,"") | C37: =IF($B37="","",INDEX('Yuri - Book'!$A:$A,$B37)) | D37: =IF($B37="","",INDEX('Yuri - Book'!$B:$B,$B37)) | E37: =IF($B37="","",INDEX('Yuri - Book'!$J:$J,$B37)) | F37: =IF($B37="","","Yuri") | G37: =IF($B37="","",INDEX('Yuri - Book'!$C:$C,$B37)) | H37: =IF($B37="","",INDEX('Yuri - Book'!$D:$D,$B37)) | I37: =IF($B37="","",INDEX('Yuri - Book'!$E:$E,$B37)) | J37: =IF($B37="","",INDEX('Yuri - Book'!$F:$F,$B37)) | K37: =IF($B37="","",INDEX('Yuri - Book'!$K:$K,$B37)) | L37: =IF($B37="","",ROUND(INDEX('Yuri - Book'!$Q:$Q,$B37),0)) | M37: =IF($B37="","",INDEX('Yuri - Book'!$P:$P,$B37))
A38: FALSE | B38: =IFERROR(MATCH(34,'Yuri - Book'!$S$4:$S$203,0)+4-1,"") | C38: =IF($B38="","",INDEX('Yuri - Book'!$A:$A,$B38)) | D38: =IF($B38="","",INDEX('Yuri - Book'!$B:$B,$B38)) | E38: =IF($B38="","",INDEX('Yuri - Book'!$J:$J,$B38)) | F38: =IF($B38="","","Yuri") | G38: =IF($B38="","",INDEX('Yuri - Book'!$C:$C,$B38)) | H38: =IF($B38="","",INDEX('Yuri - Book'!$D:$D,$B38)) | I38: =IF($B38="","",INDEX('Yuri - Book'!$E:$E,$B38)) | J38: =IF($B38="","",INDEX('Yuri - Book'!$F:$F,$B38)) | K38: =IF($B38="","",INDEX('Yuri - Book'!$K:$K,$B38)) | L38: =IF($B38="","",ROUND(INDEX('Yuri - Book'!$Q:$Q,$B38),0)) | M38: =IF($B38="","",INDEX('Yuri - Book'!$P:$P,$B38))
A39: FALSE | B39: =IFERROR(MATCH(35,'Yuri - Book'!$S$4:$S$203,0)+4-1,"") | C39: =IF($B39="","",INDEX('Yuri - Book'!$A:$A,$B39)) | D39: =IF($B39="","",INDEX('Yuri - Book'!$B:$B,$B39)) | E39: =IF($B39="","",INDEX('Yuri - Book'!$J:$J,$B39)) | F39: =IF($B39="","","Yuri") | G39: =IF($B39="","",INDEX('Yuri - Book'!$C:$C,$B39)) | H39: =IF($B39="","",INDEX('Yuri - Book'!$D:$D,$B39)) | I39: =IF($B39="","",INDEX('Yuri - Book'!$E:$E,$B39)) | J39: =IF($B39="","",INDEX('Yuri - Book'!$F:$F,$B39)) | K39: =IF($B39="","",INDEX('Yuri - Book'!$K:$K,$B39)) | L39: =IF($B39="","",ROUND(INDEX('Yuri - Book'!$Q:$Q,$B39),0)) | M39: =IF($B39="","",INDEX('Yuri - Book'!$P:$P,$B39))
A40: FALSE | B40: =IFERROR(MATCH(36,'Yuri - Book'!$S$4:$S$203,0)+4-1,"") | C40: =IF($B40="","",INDEX('Yuri - Book'!$A:$A,$B40)) | D40: =IF($B40="","",INDEX('Yuri - Book'!$B:$B,$B40)) | E40: =IF($B40="","",INDEX('Yuri - Book'!$J:$J,$B40)) | F40: =IF($B40="","","Yuri") | G40: =IF($B40="","",INDEX('Yuri - Book'!$C:$C,$B40)) | H40: =IF($B40="","",INDEX('Yuri - Book'!$D:$D,$B40)) | I40: =IF($B40="","",INDEX('Yuri - Book'!$E:$E,$B40)) | J40: =IF($B40="","",INDEX('Yuri - Book'!$F:$F,$B40)) | K40: =IF($B40="","",INDEX('Yuri - Book'!$K:$K,$B40)) | L40: =IF($B40="","",ROUND(INDEX('Yuri - Book'!$Q:$Q,$B40),0)) | M40: =IF($B40="","",INDEX('Yuri - Book'!$P:$P,$B40))
A41: FALSE | B41: =IFERROR(MATCH(37,'Yuri - Book'!$S$4:$S$203,0)+4-1,"") | C41: =IF($B41="","",INDEX('Yuri - Book'!$A:$A,$B41)) | D41: =IF($B41="","",INDEX('Yuri - Book'!$B:$B,$B41)) | E41: =IF($B41="","",INDEX('Yuri - Book'!$J:$J,$B41)) | F41: =IF($B41="","","Yuri") | G41: =IF($B41="","",INDEX('Yuri - Book'!$C:$C,$B41)) | H41: =IF($B41="","",INDEX('Yuri - Book'!$D:$D,$B41)) | I41: =IF($B41="","",INDEX('Yuri - Book'!$E:$E,$B41)) | J41: =IF($B41="","",INDEX('Yuri - Book'!$F:$F,$B41)) | K41: =IF($B41="","",INDEX('Yuri - Book'!$K:$K,$B41)) | L41: =IF($B41="","",ROUND(INDEX('Yuri - Book'!$Q:$Q,$B41),0)) | M41: =IF($B41="","",INDEX('Yuri - Book'!$P:$P,$B41))
...

Sheet Yuri - Book
A1: Yuri's Book — Player Database
A3: Player ID | B3: Player Name / Handle | C3: Source | D3: Roobet Username | E3: Status | F3: Health | G3: Priority (1=Urgent) | H3: Date Assigned | I3: Last Contact Date | J3: Next Follow-Up Due | K3: Next Action | L3: KYC Status | M3: Deposit Status | N3: Weighted Wager | O3: VIP Ready | P3: Notes | Q3: DaysSinceContact | R3: DueFlag | S3: DueRank | T3: Follow-Up Attempts | U3: ReactivationFlag | V3: ReactivationRank | W3: VIPTeamCheckinDate | X3: VIPTeamCheckinCount | Y3: UpcomingFlag | Z3: UpcomingRank | AA3: VIP Transferred Date | AB3: VIP Transferred Attempts | AC3: Transferred to VIP Team | AD3: StatusNextFollowUp | AE3: VIPTeamNextFollowUp | AF3: FTD Date
A4: =IF($B4="","","YU-"&TEXT(ROW()-3,"0000")) | C4: Discord | F4: =IF($E4="","",IF($E4="Dead Lead","Black",IF(IF(ISNUMBER($J4),TODAY()-$J4>3,FALSE),"Red",IF($E4="Reactivation Queue","Red",IF(OR($E4="First Deposit",$E4="Active"),"Green","Yellow"))))) | G4: =IF($F4="","",IF($F4="Red",1,IF($F4="Yellow",2,IF($F4="Green",3,4)))) | J4: =IF($E4="","",IF(AND(ISNUMBER($AD4),ISNUMBER($AE4)),MIN($AD4,$AE4),IF(ISNUMBER($AE4),$AE4,$AD4))) | K4: =IF($E4="","",IF($E4="VIP Transferred",IF(N($AB4)>=3,"Should be Dead Lead (3 attempts, still no deposit) - will auto-update","Day "&CHOOSE(N($AB4)+1,1,2,3)&" URGENT VIP check-in - help them finish KYC and lock in first deposit"),IF(AND($D4="",$E4<>"Dead Lead"),IF(N($T4)>=3,"READY FOR DEAD LEAD (3 attempts, still no sign-up)","GET ROOBET SIGN-UP - "&IFERROR(VLOOKUP($E4,Lists!$C$2:$E$20,2,FALSE),"")),IFERROR(VLOOKUP($E4,Lists!$C$2:$E$20,2,FALSE),""))))&IF($AC4="Yes",IF(N($X4)>=3," | VIP Team checkpoints complete - no more automatic check-ins"," | Day "&CHOOSE(N($X4)+1,1,7,14)&" VIP Team check-in - confirm active/depositing"),"") | O4: =IF($E4="","",IF(AND($E4="Active",$F4="Green"),"Yes","No")) | Q4: =IF($I4="","",ROUND(TODAY()-$I4,0)) | R4: =IF($B4="",0,IF(OR(AND(ISNUMBER($J4),$J4<=TODAY(),$E4<>"Dead Lead"),AND($D4="",$E4<>"",$E4<>"Dead Lead",OR($I4="",$I4<TODAY()))),1,0)) | S4: =IF($R4=1,SUMPRODUCT(($R$4:$R$203=1)*(($Q$4:$Q$203>$Q4)+(($Q$4:$Q$203=$Q4)*(ROW($Q$4:$Q$203)<ROW($Q4)))))+1,"") | T4: =IF($B4="","",0) | U4: =IF($B4="",0,IF($E4="Dead Lead",1,0)) | V4: =IF($U4=1,SUMPRODUCT(($U$4:$U$203=1)*(($J$4:$J$203<$J4)+(($J$4:$J$203=$J4)*(ROW($J$4:$J$203)<ROW($J4)))))+1,"") | W4: =IF($B4="","","") | X4: =IF($B4="","",0) | Y4: =IF($B4="",0,IF(AND($R4=0,$E4<>"Dead Lead",ISNUMBER($J4),$J4<=TODAY()+7),1,0)) | Z4: =IF($Y4=1,SUMPRODUCT(($Y$4:$Y$203=1)*(($J$4:$J$203<$J4)+(($J$4:$J$203=$J4)*(ROW($J$4:$J$203)<ROW($J4)))))+1,"") | AA4: =IF($B4="","","") | AB4: =IF($B4="","",0) | AD4: =IF($E4="","",IF($E4="VIP Transferred",IF($AA4="","",IF(N($AB4)>=3,"N/A - Closed",$AA4+CHOOSE(N($AB4)+1,1,2,3))),IF($I4="","",IF(VLOOKUP($E4,Lists!$C$2:$E$20,3,FALSE)="CLOSED","N/A - Closed",$I4+VLOOKUP($E4,Lists!$C$2:$E$20,3,FALSE))))) | AE4: =IF(AND($AC4="Yes",$W4<>"",N($X4)<3),$W4+CHOOSE(N($X4)+1,1,7,14),"") | AF4: =IF($B4="","","")
A5: =IF($B5="","","YU-"&TEXT(ROW()-3,"0000")) | C5: Discord | F5: =IF($E5="","",IF($E5="Dead Lead","Black",IF(IF(ISNUMBER($J5),TODAY()-$J5>3,FALSE),"Red",IF($E5="Reactivation Queue","Red",IF(OR($E5="First Deposit",$E5="Active"),"Green","Yellow"))))) | G5: =IF($F5="","",IF($F5="Red",1,IF($F5="Yellow",2,IF($F5="Green",3,4)))) | J5: =IF($E5="","",IF(AND(ISNUMBER($AD5),ISNUMBER($AE5)),MIN($AD5,$AE5),IF(ISNUMBER($AE5),$AE5,$AD5))) | K5: =IF($E5="","",IF($E5="VIP Transferred",IF(N($AB5)>=3,"Should be Dead Lead (3 attempts, still no deposit) - will auto-update","Day "&CHOOSE(N($AB5)+1,1,2,3)&" URGENT VIP check-in - help them finish KYC and lock in first deposit"),IF(AND($D5="",$E5<>"Dead Lead"),IF(N($T5)>=3,"READY FOR DEAD LEAD (3 attempts, still no sign-up)","GET ROOBET SIGN-UP - "&IFERROR(VLOOKUP($E5,Lists!$C$2:$E$20,2,FALSE),"")),IFERROR(VLOOKUP($E5,Lists!$C$2:$E$20,2,FALSE),""))))&IF($AC5="Yes",IF(N($X5)>=3," | VIP Team checkpoints complete - no more automatic check-ins"," | Day "&CHOOSE(N($X5)+1,1,7,14)&" VIP Team check-in - confirm active/depositing"),"") | O5: =IF($E5="","",IF(AND($E5="Active",$F5="Green"),"Yes","No")) | Q5: =IF($I5="","",ROUND(TODAY()-$I5,0)) | R5: =IF($B5="",0,IF(OR(AND(ISNUMBER($J5),$J5<=TODAY(),$E5<>"Dead Lead"),AND($D5="",$E5<>"",$E5<>"Dead Lead",OR($I5="",$I5<TODAY()))),1,0)) | S5: =IF($R5=1,SUMPRODUCT(($R$4:$R$203=1)*(($Q$4:$Q$203>$Q5)+(($Q$4:$Q$203=$Q5)*(ROW($Q$4:$Q$203)<ROW($Q5)))))+1,"") | T5: =IF($B5="","",0) | U5: =IF($B5="",0,IF($E5="Dead Lead",1,0)) | V5: =IF($U5=1,SUMPRODUCT(($U$4:$U$203=1)*(($J$4:$J$203<$J5)+(($J$4:$J$203=$J5)*(ROW($J$4:$J$203)<ROW($J5)))))+1,"") | W5: =IF($B5="","","") | X5: =IF($B5="","",0) | Y5: =IF($B5="",0,IF(AND($R5=0,$E5<>"Dead Lead",ISNUMBER($J5),$J5<=TODAY()+7),1,0)) | Z5: =IF($Y5=1,SUMPRODUCT(($Y$4:$Y$203=1)*(($J$4:$J$203<$J5)+(($J$4:$J$203=$J5)*(ROW($J$4:$J$203)<ROW($J5)))))+1,"") | AA5: =IF($B5="","","") | AB5: =IF($B5="","",0) | AD5: =IF($E5="","",IF($E5="VIP Transferred",IF($AA5="","",IF(N($AB5)>=3,"N/A - Closed",$AA5+CHOOSE(N($AB5)+1,1,2,3))),IF($I5="","",IF(VLOOKUP($E5,Lists!$C$2:$E$20,3,FALSE)="CLOSED","N/A - Closed",$I5+VLOOKUP($E5,Lists!$C$2:$E$20,3,FALSE))))) | AE5: =IF(AND($AC5="Yes",$W5<>"",N($X5)<3),$W5+CHOOSE(N($X5)+1,1,7,14),"") | AF5: =IF($B5="","","")
A6: =IF($B6="","","YU-"&TEXT(ROW()-3,"0000")) | C6: Discord | F6: =IF($E6="","",IF($E6="Dead Lead","Black",IF(IF(ISNUMBER($J6),TODAY()-$J6>3,FALSE),"Red",IF($E6="Reactivation Queue","Red",IF(OR($E6="First Deposit",$E6="Active"),"Green","Yellow"))))) | G6: =IF($F6="","",IF($F6="Red",1,IF($F6="Yellow",2,IF($F6="Green",3,4)))) | J6: =IF($E6="","",IF(AND(ISNUMBER($AD6),ISNUMBER($AE6)),MIN($AD6,$AE6),IF(ISNUMBER($AE6),$AE6,$AD6))) | K6: =IF($E6="","",IF($E6="VIP Transferred",IF(N($AB6)>=3,"Should be Dead Lead (3 attempts, still no deposit) - will auto-update","Day "&CHOOSE(N($AB6)+1,1,2,3)&" URGENT VIP check-in - help them finish KYC and lock in first deposit"),IF(AND($D6="",$E6<>"Dead Lead"),IF(N($T6)>=3,"READY FOR DEAD LEAD (3 attempts, still no sign-up)","GET ROOBET SIGN-UP - "&IFERROR(VLOOKUP($E6,Lists!$C$2:$E$20,2,FALSE),"")),IFERROR(VLOOKUP($E6,Lists!$C$2:$E$20,2,FALSE),""))))&IF($AC6="Yes",IF(N($X6)>=3," | VIP Team checkpoints complete - no more automatic check-ins"," | Day "&CHOOSE(N($X6)+1,1,7,14)&" VIP Team check-in - confirm active/depositing"),"") | O6: =IF($E6="","",IF(AND($E6="Active",$F6="Green"),"Yes","No")) | Q6: =IF($I6="","",ROUND(TODAY()-$I6,0)) | R6: =IF($B6="",0,IF(OR(AND(ISNUMBER($J6),$J6<=TODAY(),$E6<>"Dead Lead"),AND($D6="",$E6<>"",$E6<>"Dead Lead",OR($I6="",$I6<TODAY()))),1,0)) | S6: =IF($R6=1,SUMPRODUCT(($R$4:$R$203=1)*(($Q$4:$Q$203>$Q6)+(($Q$4:$Q$203=$Q6)*(ROW($Q$4:$Q$203)<ROW($Q6)))))+1,"") | T6: =IF($B6="","",0) | U6: =IF($B6="",0,IF($E6="Dead Lead",1,0)) | V6: =IF($U6=1,SUMPRODUCT(($U$4:$U$203=1)*(($J$4:$J$203<$J6)+(($J$4:$J$203=$J6)*(ROW($J$4:$J$203)<ROW($J6)))))+1,"") | W6: =IF($B6="","","") | X6: =IF($B6="","",0) | Y6: =IF($B6="",0,IF(AND($R6=0,$E6<>"Dead Lead",ISNUMBER($J6),$J6<=TODAY()+7),1,0)) | Z6: =IF($Y6=1,SUMPRODUCT(($Y$4:$Y$203=1)*(($J$4:$J$203<$J6)+(($J$4:$J$203=$J6)*(ROW($J$4:$J$203)<ROW($J6)))))+1,"") | AA6: =IF($B6="","","") | AB6: =IF($B6="","",0) | AD6: =IF($E6="","",IF($E6="VIP Transferred",IF($AA6="","",IF(N($AB6)>=3,"N/A - Closed",$AA6+CHOOSE(N($AB6)+1,1,2,3))),IF($I6="","",IF(VLOOKUP($E6,Lists!$C$2:$E$20,3,FALSE)="CLOSED","N/A - Closed",$I6+VLOOKUP($E6,Lists!$C$2:$E$20,3,FALSE))))) | AE6: =IF(AND($AC6="Yes",$W6<>"",N($X6)<3),$W6+CHOOSE(N($X6)+1,1,7,14),"") | AF6: =IF($B6="","","")
A7: =IF($B7="","","YU-"&TEXT(ROW()-3,"0000")) | C7: Discord | F7: =IF($E7="","",IF($E7="Dead Lead","Black",IF(IF(ISNUMBER($J7),TODAY()-$J7>3,FALSE),"Red",IF($E7="Reactivation Queue","Red",IF(OR($E7="First Deposit",$E7="Active"),"Green","Yellow"))))) | G7: =IF($F7="","",IF($F7="Red",1,IF($F7="Yellow",2,IF($F7="Green",3,4)))) | J7: =IF($E7="","",IF(AND(ISNUMBER($AD7),ISNUMBER($AE7)),MIN($AD7,$AE7),IF(ISNUMBER($AE7),$AE7,$AD7))) | K7: =IF($E7="","",IF($E7="VIP Transferred",IF(N($AB7)>=3,"Should be Dead Lead (3 attempts, still no deposit) - will auto-update","Day "&CHOOSE(N($AB7)+1,1,2,3)&" URGENT VIP check-in - help them finish KYC and lock in first deposit"),IF(AND($D7="",$E7<>"Dead Lead"),IF(N($T7)>=3,"READY FOR DEAD LEAD (3 attempts, still no sign-up)","GET ROOBET SIGN-UP - "&IFERROR(VLOOKUP($E7,Lists!$C$2:$E$20,2,FALSE),"")),IFERROR(VLOOKUP($E7,Lists!$C$2:$E$20,2,FALSE),""))))&IF($AC7="Yes",IF(N($X7)>=3," | VIP Team checkpoints complete - no more automatic check-ins"," | Day "&CHOOSE(N($X7)+1,1,7,14)&" VIP Team check-in - confirm active/depositing"),"") | O7: =IF($E7="","",IF(AND($E7="Active",$F7="Green"),"Yes","No")) | Q7: =IF($I7="","",ROUND(TODAY()-$I7,0)) | R7: =IF($B7="",0,IF(OR(AND(ISNUMBER($J7),$J7<=TODAY(),$E7<>"Dead Lead"),AND($D7="",$E7<>"",$E7<>"Dead Lead",OR($I7="",$I7<TODAY()))),1,0)) | S7: =IF($R7=1,SUMPRODUCT(($R$4:$R$203=1)*(($Q$4:$Q$203>$Q7)+(($Q$4:$Q$203=$Q7)*(ROW($Q$4:$Q$203)<ROW($Q7)))))+1,"") | T7: =IF($B7="","",0) | U7: =IF($B7="",0,IF($E7="Dead Lead",1,0)) | V7: =IF($U7=1,SUMPRODUCT(($U$4:$U$203=1)*(($J$4:$J$203<$J7)+(($J$4:$J$203=$J7)*(ROW($J$4:$J$203)<ROW($J7)))))+1,"") | W7: =IF($B7="","","") | X7: =IF($B7="","",0) | Y7: =IF($B7="",0,IF(AND($R7=0,$E7<>"Dead Lead",ISNUMBER($J7),$J7<=TODAY()+7),1,0)) | Z7: =IF($Y7=1,SUMPRODUCT(($Y$4:$Y$203=1)*(($J$4:$J$203<$J7)+(($J$4:$J$203=$J7)*(ROW($J$4:$J$203)<ROW($J7)))))+1,"") | AA7: =IF($B7="","","") | AB7: =IF($B7="","",0) | AD7: =IF($E7="","",IF($E7="VIP Transferred",IF($AA7="","",IF(N($AB7)>=3,"N/A - Closed",$AA7+CHOOSE(N($AB7)+1,1,2,3))),IF($I7="","",IF(VLOOKUP($E7,Lists!$C$2:$E$20,3,FALSE)="CLOSED","N/A - Closed",$I7+VLOOKUP($E7,Lists!$C$2:$E$20,3,FALSE))))) | AE7: =IF(AND($AC7="Yes",$W7<>"",N($X7)<3),$W7+CHOOSE(N($X7)+1,1,7,14),"") | AF7: =IF($B7="","","")
A8: =IF($B8="","","YU-"&TEXT(ROW()-3,"0000")) | C8: Discord | F8: =IF($E8="","",IF($E8="Dead Lead","Black",IF(IF(ISNUMBER($J8),TODAY()-$J8>3,FALSE),"Red",IF($E8="Reactivation Queue","Red",IF(OR($E8="First Deposit",$E8="Active"),"Green","Yellow"))))) | G8: =IF($F8="","",IF($F8="Red",1,IF($F8="Yellow",2,IF($F8="Green",3,4)))) | J8: =IF($E8="","",IF(AND(ISNUMBER($AD8),ISNUMBER($AE8)),MIN($AD8,$AE8),IF(ISNUMBER($AE8),$AE8,$AD8))) | K8: =IF($E8="","",IF($E8="VIP Transferred",IF(N($AB8)>=3,"Should be Dead Lead (3 attempts, still no deposit) - will auto-update","Day "&CHOOSE(N($AB8)+1,1,2,3)&" URGENT VIP check-in - help them finish KYC and lock in first deposit"),IF(AND($D8="",$E8<>"Dead Lead"),IF(N($T8)>=3,"READY FOR DEAD LEAD (3 attempts, still no sign-up)","GET ROOBET SIGN-UP - "&IFERROR(VLOOKUP($E8,Lists!$C$2:$E$20,2,FALSE),"")),IFERROR(VLOOKUP($E8,Lists!$C$2:$E$20,2,FALSE),""))))&IF($AC8="Yes",IF(N($X8)>=3," | VIP Team checkpoints complete - no more automatic check-ins"," | Day "&CHOOSE(N($X8)+1,1,7,14)&" VIP Team check-in - confirm active/depositing"),"") | O8: =IF($E8="","",IF(AND($E8="Active",$F8="Green"),"Yes","No")) | Q8: =IF($I8="","",ROUND(TODAY()-$I8,0)) | R8: =IF($B8="",0,IF(OR(AND(ISNUMBER($J8),$J8<=TODAY(),$E8<>"Dead Lead"),AND($D8="",$E8<>"",$E8<>"Dead Lead",OR($I8="",$I8<TODAY()))),1,0)) | S8: =IF($R8=1,SUMPRODUCT(($R$4:$R$203=1)*(($Q$4:$Q$203>$Q8)+(($Q$4:$Q$203=$Q8)*(ROW($Q$4:$Q$203)<ROW($Q8)))))+1,"") | T8: =IF($B8="","",0) | U8: =IF($B8="",0,IF($E8="Dead Lead",1,0)) | V8: =IF($U8=1,SUMPRODUCT(($U$4:$U$203=1)*(($J$4:$J$203<$J8)+(($J$4:$J$203=$J8)*(ROW($J$4:$J$203)<ROW($J8)))))+1,"") | W8: =IF($B8="","","") | X8: =IF($B8="","",0) | Y8: =IF($B8="",0,IF(AND($R8=0,$E8<>"Dead Lead",ISNUMBER($J8),$J8<=TODAY()+7),1,0)) | Z8: =IF($Y8=1,SUMPRODUCT(($Y$4:$Y$203=1)*(($J$4:$J$203<$J8)+(($J$4:$J$203=$J8)*(ROW($J$4:$J$203)<ROW($J8)))))+1,"") | AA8: =IF($B8="","","") | AB8: =IF($B8="","",0) | AD8: =IF($E8="","",IF($E8="VIP Transferred",IF($AA8="","",IF(N($AB8)>=3,"N/A - Closed",$AA8+CHOOSE(N($AB8)+1,1,2,3))),IF($I8="","",IF(VLOOKUP($E8,Lists!$C$2:$E$20,3,FALSE)="CLOSED","N/A - Closed",$I8+VLOOKUP($E8,Lists!$C$2:$E$20,3,FALSE))))) | AE8: =IF(AND($AC8="Yes",$W8<>"",N($X8)<3),$W8+CHOOSE(N($X8)+1,1,7,14),"") | AF8: =IF($B8="","","")
A9: =IF($B9="","","YU-"&TEXT(ROW()-3,"0000")) | C9: Discord | F9: =IF($E9="","",IF($E9="Dead Lead","Black",IF(IF(ISNUMBER($J9),TODAY()-$J9>3,FALSE),"Red",IF($E9="Reactivation Queue","Red",IF(OR($E9="First Deposit",$E9="Active"),"Green","Yellow"))))) | G9: =IF($F9="","",IF($F9="Red",1,IF($F9="Yellow",2,IF($F9="Green",3,4)))) | J9: =IF($E9="","",IF(AND(ISNUMBER($AD9),ISNUMBER($AE9)),MIN($AD9,$AE9),IF(ISNUMBER($AE9),$AE9,$AD9))) | K9: =IF($E9="","",IF($E9="VIP Transferred",IF(N($AB9)>=3,"Should be Dead Lead (3 attempts, still no deposit) - will auto-update","Day "&CHOOSE(N($AB9)+1,1,2,3)&" URGENT VIP check-in - help them finish KYC and lock in first deposit"),IF(AND($D9="",$E9<>"Dead Lead"),IF(N($T9)>=3,"READY FOR DEAD LEAD (3 attempts, still no sign-up)","GET ROOBET SIGN-UP - "&IFERROR(VLOOKUP($E9,Lists!$C$2:$E$20,2,FALSE),"")),IFERROR(VLOOKUP($E9,Lists!$C$2:$E$20,2,FALSE),""))))&IF($AC9="Yes",IF(N($X9)>=3," | VIP Team checkpoints complete - no more automatic check-ins"," | Day "&CHOOSE(N($X9)+1,1,7,14)&" VIP Team check-in - confirm active/depositing"),"") | O9: =IF($E9="","",IF(AND($E9="Active",$F9="Green"),"Yes","No")) | Q9: =IF($I9="","",ROUND(TODAY()-$I9,0)) | R9: =IF($B9="",0,IF(OR(AND(ISNUMBER($J9),$J9<=TODAY(),$E9<>"Dead Lead"),AND($D9="",$E9<>"",$E9<>"Dead Lead",OR($I9="",$I9<TODAY()))),1,0)) | S9: =IF($R9=1,SUMPRODUCT(($R$4:$R$203=1)*(($Q$4:$Q$203>$Q9)+(($Q$4:$Q$203=$Q9)*(ROW($Q$4:$Q$203)<ROW($Q9)))))+1,"") | T9: =IF($B9="","",0) | U9: =IF($B9="",0,IF($E9="Dead Lead",1,0)) | V9: =IF($U9=1,SUMPRODUCT(($U$4:$U$203=1)*(($J$4:$J$203<$J9)+(($J$4:$J$203=$J9)*(ROW($J$4:$J$203)<ROW($J9)))))+1,"") | W9: =IF($B9="","","") | X9: =IF($B9="","",0) | Y9: =IF($B9="",0,IF(AND($R9=0,$E9<>"Dead Lead",ISNUMBER($J9),$J9<=TODAY()+7),1,0)) | Z9: =IF($Y9=1,SUMPRODUCT(($Y$4:$Y$203=1)*(($J$4:$J$203<$J9)+(($J$4:$J$203=$J9)*(ROW($J$4:$J$203)<ROW($J9)))))+1,"") | AA9: =IF($B9="","","") | AB9: =IF($B9="","",0) | AD9: =IF($E9="","",IF($E9="VIP Transferred",IF($AA9="","",IF(N($AB9)>=3,"N/A - Closed",$AA9+CHOOSE(N($AB9)+1,1,2,3))),IF($I9="","",IF(VLOOKUP($E9,Lists!$C$2:$E$20,3,FALSE)="CLOSED","N/A - Closed",$I9+VLOOKUP($E9,Lists!$C$2:$E$20,3,FALSE))))) | AE9: =IF(AND($AC9="Yes",$W9<>"",N($X9)<3),$W9+CHOOSE(N($X9)+1,1,7,14),"") | AF9: =IF($B9="","","")
A10: =IF($B10="","","YU-"&TEXT(ROW()-3,"0000")) | C10: Discord | F10: =IF($E10="","",IF($E10="Dead Lead","Black",IF(IF(ISNUMBER($J10),TODAY()-$J10>3,FALSE),"Red",IF($E10="Reactivation Queue","Red",IF(OR($E10="First Deposit",$E10="Active"),"Green","Yellow"))))) | G10: =IF($F10="","",IF($F10="Red",1,IF($F10="Yellow",2,IF($F10="Green",3,4)))) | J10: =IF($E10="","",IF(AND(ISNUMBER($AD10),ISNUMBER($AE10)),MIN($AD10,$AE10),IF(ISNUMBER($AE10),$AE10,$AD10))) | K10: =IF($E10="","",IF($E10="VIP Transferred",IF(N($AB10)>=3,"Should be Dead Lead (3 attempts, still no deposit) - will auto-update","Day "&CHOOSE(N($AB10)+1,1,2,3)&" URGENT VIP check-in - help them finish KYC and lock in first deposit"),IF(AND($D10="",$E10<>"Dead Lead"),IF(N($T10)>=3,"READY FOR DEAD LEAD (3 attempts, still no sign-up)","GET ROOBET SIGN-UP - "&IFERROR(VLOOKUP($E10,Lists!$C$2:$E$20,2,FALSE),"")),IFERROR(VLOOKUP($E10,Lists!$C$2:$E$20,2,FALSE),""))))&IF($AC10="Yes",IF(N($X10)>=3," | VIP Team checkpoints complete - no more automatic check-ins"," | Day "&CHOOSE(N($X10)+1,1,7,14)&" VIP Team check-in - confirm active/depositing"),"") | O10: =IF($E10="","",IF(AND($E10="Active",$F10="Green"),"Yes","No")) | Q10: =IF($I10="","",ROUND(TODAY()-$I10,0)) | R10: =IF($B10="",0,IF(OR(AND(ISNUMBER($J10),$J10<=TODAY(),$E10<>"Dead Lead"),AND($D10="",$E10<>"",$E10<>"Dead Lead",OR($I10="",$I10<TODAY()))),1,0)) | S10: =IF($R10=1,SUMPRODUCT(($R$4:$R$203=1)*(($Q$4:$Q$203>$Q10)+(($Q$4:$Q$203=$Q10)*(ROW($Q$4:$Q$203)<ROW($Q10)))))+1,"") | T10: =IF($B10="","",0) | U10: =IF($B10="",0,IF($E10="Dead Lead",1,0)) | V10: =IF($U10=1,SUMPRODUCT(($U$4:$U$203=1)*(($J$4:$J$203<$J10)+(($J$4:$J$203=$J10)*(ROW($J$4:$J$203)<ROW($J10)))))+1,"") | W10: =IF($B10="","","") | X10: =IF($B10="","",0) | Y10: =IF($B10="",0,IF(AND($R10=0,$E10<>"Dead Lead",ISNUMBER($J10),$J10<=TODAY()+7),1,0)) | Z10: =IF($Y10=1,SUMPRODUCT(($Y$4:$Y$203=1)*(($J$4:$J$203<$J10)+(($J$4:$J$203=$J10)*(ROW($J$4:$J$203)<ROW($J10)))))+1,"") | AA10: =IF($B10="","","") | AB10: =IF($B10="","",0) | AD10: =IF($E10="","",IF($E10="VIP Transferred",IF($AA10="","",IF(N($AB10)>=3,"N/A - Closed",$AA10+CHOOSE(N($AB10)+1,1,2,3))),IF($I10="","",IF(VLOOKUP($E10,Lists!$C$2:$E$20,3,FALSE)="CLOSED","N/A - Closed",$I10+VLOOKUP($E10,Lists!$C$2:$E$20,3,FALSE))))) | AE10: =IF(AND($AC10="Yes",$W10<>"",N($X10)<3),$W10+CHOOSE(N($X10)+1,1,7,14),"") | AF10: =IF($B10="","","")
A11: =IF($B11="","","YU-"&TEXT(ROW()-3,"0000")) | C11: Discord | F11: =IF($E11="","",IF($E11="Dead Lead","Black",IF(IF(ISNUMBER($J11),TODAY()-$J11>3,FALSE),"Red",IF($E11="Reactivation Queue","Red",IF(OR($E11="First Deposit",$E11="Active"),"Green","Yellow"))))) | G11: =IF($F11="","",IF($F11="Red",1,IF($F11="Yellow",2,IF($F11="Green",3,4)))) | J11: =IF($E11="","",IF(AND(ISNUMBER($AD11),ISNUMBER($AE11)),MIN($AD11,$AE11),IF(ISNUMBER($AE11),$AE11,$AD11))) | K11: =IF($E11="","",IF($E11="VIP Transferred",IF(N($AB11)>=3,"Should be Dead Lead (3 attempts, still no deposit) - will auto-update","Day "&CHOOSE(N($AB11)+1,1,2,3)&" URGENT VIP check-in - help them finish KYC and lock in first deposit"),IF(AND($D11="",$E11<>"Dead Lead"),IF(N($T11)>=3,"READY FOR DEAD LEAD (3 attempts, still no sign-up)","GET ROOBET SIGN-UP - "&IFERROR(VLOOKUP($E11,Lists!$C$2:$E$20,2,FALSE),"")),IFERROR(VLOOKUP($E11,Lists!$C$2:$E$20,2,FALSE),""))))&IF($AC11="Yes",IF(N($X11)>=3," | VIP Team checkpoints complete - no more automatic check-ins"," | Day "&CHOOSE(N($X11)+1,1,7,14)&" VIP Team check-in - confirm active/depositing"),"") | O11: =IF($E11="","",IF(AND($E11="Active",$F11="Green"),"Yes","No")) | Q11: =IF($I11="","",ROUND(TODAY()-$I11,0)) | R11: =IF($B11="",0,IF(OR(AND(ISNUMBER($J11),$J11<=TODAY(),$E11<>"Dead Lead"),AND($D11="",$E11<>"",$E11<>"Dead Lead",OR($I11="",$I11<TODAY()))),1,0)) | S11: =IF($R11=1,SUMPRODUCT(($R$4:$R$203=1)*(($Q$4:$Q$203>$Q11)+(($Q$4:$Q$203=$Q11)*(ROW($Q$4:$Q$203)<ROW($Q11)))))+1,"") | T11: =IF($B11="","",0) | U11: =IF($B11="",0,IF($E11="Dead Lead",1,0)) | V11: =IF($U11=1,SUMPRODUCT(($U$4:$U$203=1)*(($J$4:$J$203<$J11)+(($J$4:$J$203=$J11)*(ROW($J$4:$J$203)<ROW($J11)))))+1,"") | W11: =IF($B11="","","") | X11: =IF($B11="","",0) | Y11: =IF($B11="",0,IF(AND($R11=0,$E11<>"Dead Lead",ISNUMBER($J11),$J11<=TODAY()+7),1,0)) | Z11: =IF($Y11=1,SUMPRODUCT(($Y$4:$Y$203=1)*(($J$4:$J$203<$J11)+(($J$4:$J$203=$J11)*(ROW($J$4:$J$203)<ROW($J11)))))+1,"") | AA11: =IF($B11="","","") | AB11: =IF($B11="","",0) | AD11: =IF($E11="","",IF($E11="VIP Transferred",IF($AA11="","",IF(N($AB11)>=3,"N/A - Closed",$AA11+CHOOSE(N($AB11)+1,1,2,3))),IF($I11="","",IF(VLOOKUP($E11,Lists!$C$2:$E$20,3,FALSE)="CLOSED","N/A - Closed",$I11+VLOOKUP($E11,Lists!$C$2:$E$20,3,FALSE))))) | AE11: =IF(AND($AC11="Yes",$W11<>"",N($X11)<3),$W11+CHOOSE(N($X11)+1,1,7,14),"") | AF11: =IF($B11="","","")
A12: =IF($B12="","","YU-"&TEXT(ROW()-3,"0000")) | C12: Discord | F12: =IF($E12="","",IF($E12="Dead Lead","Black",IF(IF(ISNUMBER($J12),TODAY()-$J12>3,FALSE),"Red",IF($E12="Reactivation Queue","Red",IF(OR($E12="First Deposit",$E12="Active"),"Green","Yellow"))))) | G12: =IF($F12="","",IF($F12="Red",1,IF($F12="Yellow",2,IF($F12="Green",3,4)))) | J12: =IF($E12="","",IF(AND(ISNUMBER($AD12),ISNUMBER($AE12)),MIN($AD12,$AE12),IF(ISNUMBER($AE12),$AE12,$AD12))) | K12: =IF($E12="","",IF($E12="VIP Transferred",IF(N($AB12)>=3,"Should be Dead Lead (3 attempts, still no deposit) - will auto-update","Day "&CHOOSE(N($AB12)+1,1,2,3)&" URGENT VIP check-in - help them finish KYC and lock in first deposit"),IF(AND($D12="",$E12<>"Dead Lead"),IF(N($T12)>=3,"READY FOR DEAD LEAD (3 attempts, still no sign-up)","GET ROOBET SIGN-UP - "&IFERROR(VLOOKUP($E12,Lists!$C$2:$E$20,2,FALSE),"")),IFERROR(VLOOKUP($E12,Lists!$C$2:$E$20,2,FALSE),""))))&IF($AC12="Yes",IF(N($X12)>=3," | VIP Team checkpoints complete - no more automatic check-ins"," | Day "&CHOOSE(N($X12)+1,1,7,14)&" VIP Team check-in - confirm active/depositing"),"") | O12: =IF($E12="","",IF(AND($E12="Active",$F12="Green"),"Yes","No")) | Q12: =IF($I12="","",ROUND(TODAY()-$I12,0)) | R12: =IF($B12="",0,IF(OR(AND(ISNUMBER($J12),$J12<=TODAY(),$E12<>"Dead Lead"),AND($D12="",$E12<>"",$E12<>"Dead Lead",OR($I12="",$I12<TODAY()))),1,0)) | S12: =IF($R12=1,SUMPRODUCT(($R$4:$R$203=1)*(($Q$4:$Q$203>$Q12)+(($Q$4:$Q$203=$Q12)*(ROW($Q$4:$Q$203)<ROW($Q12)))))+1,"") | T12: =IF($B12="","",0) | U12: =IF($B12="",0,IF($E12="Dead Lead",1,0)) | V12: =IF($U12=1,SUMPRODUCT(($U$4:$U$203=1)*(($J$4:$J$203<$J12)+(($J$4:$J$203=$J12)*(ROW($J$4:$J$203)<ROW($J12)))))+1,"") | W12: =IF($B12="","","") | X12: =IF($B12="","",0) | Y12: =IF($B12="",0,IF(AND($R12=0,$E12<>"Dead Lead",ISNUMBER($J12),$J12<=TODAY()+7),1,0)) | Z12: =IF($Y12=1,SUMPRODUCT(($Y$4:$Y$203=1)*(($J$4:$J$203<$J12)+(($J$4:$J$203=$J12)*(ROW($J$4:$J$203)<ROW($J12)))))+1,"") | AA12: =IF($B12="","","") | AB12: =IF($B12="","",0) | AD12: =IF($E12="","",IF($E12="VIP Transferred",IF($AA12="","",IF(N($AB12)>=3,"N/A - Closed",$AA12+CHOOSE(N($AB12)+1,1,2,3))),IF($I12="","",IF(VLOOKUP($E12,Lists!$C$2:$E$20,3,FALSE)="CLOSED","N/A - Closed",$I12+VLOOKUP($E12,Lists!$C$2:$E$20,3,FALSE))))) | AE12: =IF(AND($AC12="Yes",$W12<>"",N($X12)<3),$W12+CHOOSE(N($X12)+1,1,7,14),"") | AF12: =IF($B12="","","")
A13: =IF($B13="","","YU-"&TEXT(ROW()-3,"0000")) | C13: Discord | F13: =IF($E13="","",IF($E13="Dead Lead","Black",IF(IF(ISNUMBER($J13),TODAY()-$J13>3,FALSE),"Red",IF($E13="Reactivation Queue","Red",IF(OR($E13="First Deposit",$E13="Active"),"Green","Yellow"))))) | G13: =IF($F13="","",IF($F13="Red",1,IF($F13="Yellow",2,IF($F13="Green",3,4)))) | J13: =IF($E13="","",IF(AND(ISNUMBER($AD13),ISNUMBER($AE13)),MIN($AD13,$AE13),IF(ISNUMBER($AE13),$AE13,$AD13))) | K13: =IF($E13="","",IF($E13="VIP Transferred",IF(N($AB13)>=3,"Should be Dead Lead (3 attempts, still no deposit) - will auto-update","Day "&CHOOSE(N($AB13)+1,1,2,3)&" URGENT VIP check-in - help them finish KYC and lock in first deposit"),IF(AND($D13="",$E13<>"Dead Lead"),IF(N($T13)>=3,"READY FOR DEAD LEAD (3 attempts, still no sign-up)","GET ROOBET SIGN-UP - "&IFERROR(VLOOKUP($E13,Lists!$C$2:$E$20,2,FALSE),"")),IFERROR(VLOOKUP($E13,Lists!$C$2:$E$20,2,FALSE),""))))&IF($AC13="Yes",IF(N($X13)>=3," | VIP Team checkpoints complete - no more automatic check-ins"," | Day "&CHOOSE(N($X13)+1,1,7,14)&" VIP Team check-in - confirm active/depositing"),"") | O13: =IF($E13="","",IF(AND($E13="Active",$F13="Green"),"Yes","No")) | Q13: =IF($I13="","",ROUND(TODAY()-$I13,0)) | R13: =IF($B13="",0,IF(OR(AND(ISNUMBER($J13),$J13<=TODAY(),$E13<>"Dead Lead"),AND($D13="",$E13<>"",$E13<>"Dead Lead",OR($I13="",$I13<TODAY()))),1,0)) | S13: =IF($R13=1,SUMPRODUCT(($R$4:$R$203=1)*(($Q$4:$Q$203>$Q13)+(($Q$4:$Q$203=$Q13)*(ROW($Q$4:$Q$203)<ROW($Q13)))))+1,"") | T13: =IF($B13="","",0) | U13: =IF($B13="",0,IF($E13="Dead Lead",1,0)) | V13: =IF($U13=1,SUMPRODUCT(($U$4:$U$203=1)*(($J$4:$J$203<$J13)+(($J$4:$J$203=$J13)*(ROW($J$4:$J$203)<ROW($J13)))))+1,"") | W13: =IF($B13="","","") | X13: =IF($B13="","",0) | Y13: =IF($B13="",0,IF(AND($R13=0,$E13<>"Dead Lead",ISNUMBER($J13),$J13<=TODAY()+7),1,0)) | Z13: =IF($Y13=1,SUMPRODUCT(($Y$4:$Y$203=1)*(($J$4:$J$203<$J13)+(($J$4:$J$203=$J13)*(ROW($J$4:$J$203)<ROW($J13)))))+1,"") | AA13: =IF($B13="","","") | AB13: =IF($B13="","",0) | AD13: =IF($E13="","",IF($E13="VIP Transferred",IF($AA13="","",IF(N($AB13)>=3,"N/A - Closed",$AA13+CHOOSE(N($AB13)+1,1,2,3))),IF($I13="","",IF(VLOOKUP($E13,Lists!$C$2:$E$20,3,FALSE)="CLOSED","N/A - Closed",$I13+VLOOKUP($E13,Lists!$C$2:$E$20,3,FALSE))))) | AE13: =IF(AND($AC13="Yes",$W13<>"",N($X13)<3),$W13+CHOOSE(N($X13)+1,1,7,14),"") | AF13: =IF($B13="","","")
A14: =IF($B14="","","YU-"&TEXT(ROW()-3,"0000")) | C14: Discord | F14: =IF($E14="","",IF($E14="Dead Lead","Black",IF(IF(ISNUMBER($J14),TODAY()-$J14>3,FALSE),"Red",IF($E14="Reactivation Queue","Red",IF(OR($E14="First Deposit",$E14="Active"),"Green","Yellow"))))) | G14: =IF($F14="","",IF($F14="Red",1,IF($F14="Yellow",2,IF($F14="Green",3,4)))) | J14: =IF($E14="","",IF(AND(ISNUMBER($AD14),ISNUMBER($AE14)),MIN($AD14,$AE14),IF(ISNUMBER($AE14),$AE14,$AD14))) | K14: =IF($E14="","",IF($E14="VIP Transferred",IF(N($AB14)>=3,"Should be Dead Lead (3 attempts, still no deposit) - will auto-update","Day "&CHOOSE(N($AB14)+1,1,2,3)&" URGENT VIP check-in - help them finish KYC and lock in first deposit"),IF(AND($D14="",$E14<>"Dead Lead"),IF(N($T14)>=3,"READY FOR DEAD LEAD (3 attempts, still no sign-up)","GET ROOBET SIGN-UP - "&IFERROR(VLOOKUP($E14,Lists!$C$2:$E$20,2,FALSE),"")),IFERROR(VLOOKUP($E14,Lists!$C$2:$E$20,2,FALSE),""))))&IF($AC14="Yes",IF(N($X14)>=3," | VIP Team checkpoints complete - no more automatic check-ins"," | Day "&CHOOSE(N($X14)+1,1,7,14)&" VIP Team check-in - confirm active/depositing"),"") | O14: =IF($E14="","",IF(AND($E14="Active",$F14="Green"),"Yes","No")) | Q14: =IF($I14="","",ROUND(TODAY()-$I14,0)) | R14: =IF($B14="",0,IF(OR(AND(ISNUMBER($J14),$J14<=TODAY(),$E14<>"Dead Lead"),AND($D14="",$E14<>"",$E14<>"Dead Lead",OR($I14="",$I14<TODAY()))),1,0)) | S14: =IF($R14=1,SUMPRODUCT(($R$4:$R$203=1)*(($Q$4:$Q$203>$Q14)+(($Q$4:$Q$203=$Q14)*(ROW($Q$4:$Q$203)<ROW($Q14)))))+1,"") | T14: =IF($B14="","",0) | U14: =IF($B14="",0,IF($E14="Dead Lead",1,0)) | V14: =IF($U14=1,SUMPRODUCT(($U$4:$U$203=1)*(($J$4:$J$203<$J14)+(($J$4:$J$203=$J14)*(ROW($J$4:$J$203)<ROW($J14)))))+1,"") | W14: =IF($B14="","","") | X14: =IF($B14="","",0) | Y14: =IF($B14="",0,IF(AND($R14=0,$E14<>"Dead Lead",ISNUMBER($J14),$J14<=TODAY()+7),1,0)) | Z14: =IF($Y14=1,SUMPRODUCT(($Y$4:$Y$203=1)*(($J$4:$J$203<$J14)+(($J$4:$J$203=$J14)*(ROW($J$4:$J$203)<ROW($J14)))))+1,"") | AA14: =IF($B14="","","") | AB14: =IF($B14="","",0) | AD14: =IF($E14="","",IF($E14="VIP Transferred",IF($AA14="","",IF(N($AB14)>=3,"N/A - Closed",$AA14+CHOOSE(N($AB14)+1,1,2,3))),IF($I14="","",IF(VLOOKUP($E14,Lists!$C$2:$E$20,3,FALSE)="CLOSED","N/A - Closed",$I14+VLOOKUP($E14,Lists!$C$2:$E$20,3,FALSE))))) | AE14: =IF(AND($AC14="Yes",$W14<>"",N($X14)<3),$W14+CHOOSE(N($X14)+1,1,7,14),"") | AF14: =IF($B14="","","")
A15: =IF($B15="","","YU-"&TEXT(ROW()-3,"0000")) | C15: Discord | F15: =IF($E15="","",IF($E15="Dead Lead","Black",IF(IF(ISNUMBER($J15),TODAY()-$J15>3,FALSE),"Red",IF($E15="Reactivation Queue","Red",IF(OR($E15="First Deposit",$E15="Active"),"Green","Yellow"))))) | G15: =IF($F15="","",IF($F15="Red",1,IF($F15="Yellow",2,IF($F15="Green",3,4)))) | J15: =IF($E15="","",IF(AND(ISNUMBER($AD15),ISNUMBER($AE15)),MIN($AD15,$AE15),IF(ISNUMBER($AE15),$AE15,$AD15))) | K15: =IF($E15="","",IF($E15="VIP Transferred",IF(N($AB15)>=3,"Should be Dead Lead (3 attempts, still no deposit) - will auto-update","Day "&CHOOSE(N($AB15)+1,1,2,3)&" URGENT VIP check-in - help them finish KYC and lock in first deposit"),IF(AND($D15="",$E15<>"Dead Lead"),IF(N($T15)>=3,"READY FOR DEAD LEAD (3 attempts, still no sign-up)","GET ROOBET SIGN-UP - "&IFERROR(VLOOKUP($E15,Lists!$C$2:$E$20,2,FALSE),"")),IFERROR(VLOOKUP($E15,Lists!$C$2:$E$20,2,FALSE),""))))&IF($AC15="Yes",IF(N($X15)>=3," | VIP Team checkpoints complete - no more automatic check-ins"," | Day "&CHOOSE(N($X15)+1,1,7,14)&" VIP Team check-in - confirm active/depositing"),"") | O15: =IF($E15="","",IF(AND($E15="Active",$F15="Green"),"Yes","No")) | Q15: =IF($I15="","",ROUND(TODAY()-$I15,0)) | R15: =IF($B15="",0,IF(OR(AND(ISNUMBER($J15),$J15<=TODAY(),$E15<>"Dead Lead"),AND($D15="",$E15<>"",$E15<>"Dead Lead",OR($I15="",$I15<TODAY()))),1,0)) | S15: =IF($R15=1,SUMPRODUCT(($R$4:$R$203=1)*(($Q$4:$Q$203>$Q15)+(($Q$4:$Q$203=$Q15)*(ROW($Q$4:$Q$203)<ROW($Q15)))))+1,"") | T15: =IF($B15="","",0) | U15: =IF($B15="",0,IF($E15="Dead Lead",1,0)) | V15: =IF($U15=1,SUMPRODUCT(($U$4:$U$203=1)*(($J$4:$J$203<$J15)+(($J$4:$J$203=$J15)*(ROW($J$4:$J$203)<ROW($J15)))))+1,"") | W15: =IF($B15="","","") | X15: =IF($B15="","",0) | Y15: =IF($B15="",0,IF(AND($R15=0,$E15<>"Dead Lead",ISNUMBER($J15),$J15<=TODAY()+7),1,0)) | Z15: =IF($Y15=1,SUMPRODUCT(($Y$4:$Y$203=1)*(($J$4:$J$203<$J15)+(($J$4:$J$203=$J15)*(ROW($J$4:$J$203)<ROW($J15)))))+1,"") | AA15: =IF($B15="","","") | AB15: =IF($B15="","",0) | AD15: =IF($E15="","",IF($E15="VIP Transferred",IF($AA15="","",IF(N($AB15)>=3,"N/A - Closed",$AA15+CHOOSE(N($AB15)+1,1,2,3))),IF($I15="","",IF(VLOOKUP($E15,Lists!$C$2:$E$20,3,FALSE)="CLOSED","N/A - Closed",$I15+VLOOKUP($E15,Lists!$C$2:$E$20,3,FALSE))))) | AE15: =IF(AND($AC15="Yes",$W15<>"",N($X15)<3),$W15+CHOOSE(N($X15)+1,1,7,14),"") | AF15: =IF($B15="","","")
