Workbook

Sheet Read Me
B2: Daily Gamba — Master Dashboard
B3: Company-wide view, pulled live from each rep's own sheet. This file is read-only - edit a player on their rep's own Book tab, not here.
B6: What's in this file
B7: Master Player DB | C7: — Every player, every rep, combined into one view.
B8: VIP Pipeline | C8: — Every player in the VIP fast-track or handed to the in-house VIP team, company-wide, with overdue check-ins flagged in red.
B9: Overdue Follow-Ups | C9: — Every lead, any rep, that's sat untouched 24+ hours past its Next Follow-Up Due date - company-wide, all in red.
B10: Executive Dashboard | C10: — Today / This Week / This Month numbers vs. daily targets, company-wide.
B11: Team & KPI Targets | C11: — Every rep's daily targets in one table, pulled from their own files.
B13: One-time setup
B14: First time you open this | C14: — Google will ask you to "Allow access" for each rep's sheet it's pulling from (via a function called IMPORTRANGE). Click Allow once per rep and it's done permanently.
B15: Adding a new rep | C15: — Once a new rep's file exists, tell Claude their Google Sheet URL and it gets added here automatically - no other changes needed.

Sheet Master Player DB
A1: Master Player Database - All Reps Combined
A2: Live-pulled from every rep's Book tab, auto-compacted - blank capacity rows are stripped out so every rep's real leads sit back-to-back with no scrolling through empty space between reps. Read-only - to change a player's info, edit it on that rep's own Book tab, not here.
A4: Rep | B4: Player ID | C4: Player Handle | D4: Source | E4: Roobet Username | F4: Status | G4: Health | H4: Date Assigned | I4: Last Contact Date | J4: Next Follow-Up | K4: Next Action | L4: KYC Status | M4: Deposit Status | N4: Weighted Wager | O4: VIP Ready | P4: Transferred to VIP Team
A5: =IFERROR(FILTER({IF('_Import Tuna Book'!B1:B200="","","Tuna"), '_Import Tuna Book'!A1:F200, '_Import Tuna Book'!H1:O200, IFERROR('_Import Tuna VIPTeam'!B1:B200,""); IF('_Import Plat Book'!B1:B200="","","Plat"), '_Import Plat Book'!A1:F200, '_Import Plat Book'!H1:O200, IFERROR('_Import Plat VIPTeam'!B1:B200,""); IF('_Import Chella Book'!B1:B200="","","Chella"), '_Import Chella Book'!A1:F200, '_Import Chella Book'!H1:O200, IFERROR('_Import Chella VIPTeam'!B1:B200,""); IF('_Import Moneyheist Book'!B1:B200="","","Moneyheist"), '_Import Moneyheist Book'!A1:F200, '_Import Moneyheist Book'!H1:O200, IFERROR('_Import Moneyheist VIPTeam'!B1:B200,""); IF('_Import Seb Book'!B1:B200="","","Seb"), '_Import Seb Book'!A1:F200, '_Import Seb Book'!H1:O200, IFERROR('_Import Seb VIPTeam'!B1:B200,""); IF('_Import Pricey Book'!B1:B200="","","Pricey"), '_Import Pricey Book'!A1:F200, '_Import Pricey Book'!H1:O200, IFERROR('_Import Pricey VIPTeam'!B1:B200,""); IF('_Import Seanok Book'!B1:B200="","","Seanok"), '_Import Seanok Book'!A1:F200, '_Import Seanok Book'!H1:O200, IFERROR('_Import Seanok VIPTeam'!B1:B200,""); IF('_Import Gwen Book'!B1:B200="","","Gwen"), '_Import Gwen Book'!A1:F200, '_Import Gwen Book'!H1:O200, IFERROR('_Import Gwen VIPTeam'!B1:B200,""); IF('_Import Miko Book'!B1:B200="","","Miko"), '_Import Miko Book'!A1:F200, '_Import Miko Book'!H1:O200, IFERROR('_Import Miko VIPTeam'!B1:B200,""); IF('_Import Concept Book'!B1:B200="","","Concept"), '_Import Concept Book'!A1:F200, '_Import Concept Book'!H1:O200, IFERROR('_Import Concept VIPTeam'!B1:B200,""); IF('_Import Daily Book'!B1:B200="","","Daily"), '_Import Daily Book'!A1:F200, '_Import Daily Book'!H1:O200, IFERROR('_Import Daily VIPTeam'!B1:B200,""); IF('_Import Prime Book'!B1:B200="","","Prime"), '_Import Prime Book'!A1:F200, '_Import Prime Book'!H1:O200, IFERROR('_Import Prime VIPTeam'!B1:B200,""); IF('_Import Yuri Book'!B1:B200="","","Yuri"), '_Import Yuri Book'!A1:F200, '_Import Yuri Book'!H1:O200, IFERROR('_Import Yuri VIPTeam'!B1:B200,"")}, {'_Import Tuna Book'!B1:B200<>""; '_Import Plat Book'!B1:B200<>""; '_Import Chella Book'!B1:B200<>""; '_Import Moneyheist Book'!B1:B200<>""; '_Import Seb Book'!B1:B200<>""; '_Import Pricey Book'!B1:B200<>""; '_Import Seanok Book'!B1:B200<>""; '_Import Gwen Book'!B1:B200<>""; '_Import Miko Book'!B1:B200<>""; '_Import Concept Book'!B1:B200<>""; '_Import Daily Book'!B1:B200<>""; '_Import Prime Book'!B1:B200<>""; '_Import Yuri Book'!B1:B200<>""}), "")

Sheet Master FTD List
A1: Master FTD List - First Time Depositors, All Reps Combined
A2: Live-pulled from every rep's own FTD List tab, auto-compacted. Read-only - to add a player or update their Total Wager, do it on that rep's own FTD List tab, not here. A row highlighted red on a rep's own tab (stagnant wager) won't show that color here - check the rep's own FTD List to see who needs a check-in.
A3: Total Weighted Wager (all reps, current): | B3: =SUM(E5:E2604)
A4: Rep | B4: Player Handle | C4: Roobet Username | D4: FTD Date | E4: Weighted Wager
A5: =IFERROR(FILTER({IFERROR(IF('_Import Tuna FtdList'!A1:A200="","","Tuna"),""), IFERROR('_Import Tuna FtdList'!A1:D200,""); IFERROR(IF('_Import Plat FtdList'!A1:A200="","","Plat"),""), IFERROR('_Import Plat FtdList'!A1:D200,""); IFERROR(IF('_Import Chella FtdList'!A1:A200="","","Chella"),""), IFERROR('_Import Chella FtdList'!A1:D200,""); IFERROR(IF('_Import Moneyheist FtdList'!A1:A200="","","Moneyheist"),""), IFERROR('_Import Moneyheist FtdList'!A1:D200,""); IFERROR(IF('_Import Seb FtdList'!A1:A200="","","Seb"),""), IFERROR('_Import Seb FtdList'!A1:D200,""); IFERROR(IF('_Import Pricey FtdList'!A1:A200="","","Pricey"),""), IFERROR('_Import Pricey FtdList'!A1:D200,""); IFERROR(IF('_Import Seanok FtdList'!A1:A200="","","Seanok"),""), IFERROR('_Import Seanok FtdList'!A1:D200,""); IFERROR(IF('_Import Gwen FtdList'!A1:A200="","","Gwen"),""), IFERROR('_Import Gwen FtdList'!A1:D200,""); IFERROR(IF('_Import Miko FtdList'!A1:A200="","","Miko"),""), IFERROR('_Import Miko FtdList'!A1:D200,""); IFERROR(IF('_Import Concept FtdList'!A1:A200="","","Concept"),""), IFERROR('_Import Concept FtdList'!A1:D200,""); IFERROR(IF('_Import Daily FtdList'!A1:A200="","","Daily"),""), IFERROR('_Import Daily FtdList'!A1:D200,""); IFERROR(IF('_Import Prime FtdList'!A1:A200="","","Prime"),""), IFERROR('_Import Prime FtdList'!A1:D200,""); IFERROR(IF('_Import Yuri FtdList'!A1:A200="","","Yuri"),""), IFERROR('_Import Yuri FtdList'!A1:D200,"")}, {IFERROR('_Import Tuna FtdList'!A1:A200<>"",FALSE); IFERROR('_Import Plat FtdList'!A1:A200<>"",FALSE); IFERROR('_Import Chella FtdList'!A1:A200<>"",FALSE); IFERROR('_Import Moneyheist FtdList'!A1:A200<>"",FALSE); IFERROR('_Import Seb FtdList'!A1:A200<>"",FALSE); IFERROR('_Import Pricey FtdList'!A1:A200<>"",FALSE); IFERROR('_Import Seanok FtdList'!A1:A200<>"",FALSE); IFERROR('_Import Gwen FtdList'!A1:A200<>"",FALSE); IFERROR('_Import Miko FtdList'!A1:A200<>"",FALSE); IFERROR('_Import Concept FtdList'!A1:A200<>"",FALSE); IFERROR('_Import Daily FtdList'!A1:A200<>"",FALSE); IFERROR('_Import Prime FtdList'!A1:A200<>"",FALSE); IFERROR('_Import Yuri FtdList'!A1:A200<>"",FALSE)}), "")

Sheet VIP Pipeline
A1: VIP Pipeline - All Reps Combined
A2: Every player currently being handled by the in-house VIP team, or in the pre-deposit VIP fast-track, across every rep. Read-only. Rows in red are overdue for their next check-in - go to that rep's own Daily Task to act on it.
A4: Rep | B4: Player Handle | C4: Source | D4: Roobet Username | E4: Status | F4: Health | G4: Transferred to VIP Team | H4: Transferred Date | I4: Last Contact Date | J4: Next Follow-Up Due | K4: Next Action
A5: =SORT(IFERROR(FILTER({IFERROR(IF('_Import Tuna Book'!B1:B200="","","Tuna"),""), IFERROR('_Import Tuna Book'!B1:F200,""), IFERROR(IFERROR('_Import Tuna VIPTeam'!B1:B200,""),""), IFERROR(IF(IFERROR('_Import Tuna VIPTeam'!C1:C200,"")<>"",IFERROR('_Import Tuna VIPTeam'!C1:C200,""),IFERROR('_Import Tuna VIPTeam'!D1:D200,"")),""), IFERROR('_Import Tuna Book'!I1:K200,""); IFERROR(IF('_Import Plat Book'!B1:B200="","","Plat"),""), IFERROR('_Import Plat Book'!B1:F200,""), IFERROR(IFERROR('_Import Plat VIPTeam'!B1:B200,""),""), IFERROR(IF(IFERROR('_Import Plat VIPTeam'!C1:C200,"")<>"",IFERROR('_Import Plat VIPTeam'!C1:C200,""),IFERROR('_Import Plat VIPTeam'!D1:D200,"")),""), IFERROR('_Import Plat Book'!I1:K200,""); IFERROR(IF('_Import Chella Book'!B1:B200="","","Chella"),""), IFERROR('_Import Chella Book'!B1:F200,""), IFERROR(IFERROR('_Import Chella VIPTeam'!B1:B200,""),""), IFERROR(IF(IFERROR('_Import Chella VIPTeam'!C1:C200,"")<>"",IFERROR('_Import Chella VIPTeam'!C1:C200,""),IFERROR('_Import Chella VIPTeam'!D1:D200,"")),""), IFERROR('_Import Chella Book'!I1:K200,""); IFERROR(IF('_Import Moneyheist Book'!B1:B200="","","Moneyheist"),""), IFERROR('_Import Moneyheist Book'!B1:F200,""), IFERROR(IFERROR('_Import Moneyheist VIPTeam'!B1:B200,""),""), IFERROR(IF(IFERROR('_Import Moneyheist VIPTeam'!C1:C200,"")<>"",IFERROR('_Import Moneyheist VIPTeam'!C1:C200,""),IFERROR('_Import Moneyheist VIPTeam'!D1:D200,"")),""), IFERROR('_Import Moneyheist Book'!I1:K200,""); IFERROR(IF('_Import Seb Book'!B1:B200="","","Seb"),""), IFERROR('_Import Seb Book'!B1:F200,""), IFERROR(IFERROR('_Import Seb VIPTeam'!B1:B200,""),""), IFERROR(IF(IFERROR('_Import Seb VIPTeam'!C1:C200,"")<>"",IFERROR('_Import Seb VIPTeam'!C1:C200,""),IFERROR('_Import Seb VIPTeam'!D1:D200,"")),""), IFERROR('_Import Seb Book'!I1:K200,""); IFERROR(IF('_Import Pricey Book'!B1:B200="","","Pricey"),""), IFERROR('_Import Pricey Book'!B1:F200,""), IFERROR(IFERROR('_Import Pricey VIPTeam'!B1:B200,""),""), IFERROR(IF(IFERROR('_Import Pricey VIPTeam'!C1:C200,"")<>"",IFERROR('_Import Pricey VIPTeam'!C1:C200,""),IFERROR('_Import Pricey VIPTeam'!D1:D200,"")),""), IFERROR('_Import Pricey Book'!I1:K200,""); IFERROR(IF('_Import Seanok Book'!B1:B200="","","Seanok"),""), IFERROR('_Import Seanok Book'!B1:F200,""), IFERROR(IFERROR('_Import Seanok VIPTeam'!B1:B200,""),""), IFERROR(IF(IFERROR('_Import Seanok VIPTeam'!C1:C200,"")<>"",IFERROR('_Import Seanok VIPTeam'!C1:C200,""),IFERROR('_Import Seanok VIPTeam'!D1:D200,"")),""), IFERROR('_Import Seanok Book'!I1:K200,""); IFERROR(IF('_Import Gwen Book'!B1:B200="","","Gwen"),""), IFERROR('_Import Gwen Book'!B1:F200,""), IFERROR(IFERROR('_Import Gwen VIPTeam'!B1:B200,""),""), IFERROR(IF(IFERROR('_Import Gwen VIPTeam'!C1:C200,"")<>"",IFERROR('_Import Gwen VIPTeam'!C1:C200,""),IFERROR('_Import Gwen VIPTeam'!D1:D200,"")),""), IFERROR('_Import Gwen Book'!I1:K200,""); IFERROR(IF('_Import Miko Book'!B1:B200="","","Miko"),""), IFERROR('_Import Miko Book'!B1:F200,""), IFERROR(IFERROR('_Import Miko VIPTeam'!B1:B200,""),""), IFERROR(IF(IFERROR('_Import Miko VIPTeam'!C1:C200,"")<>"",IFERROR('_Import Miko VIPTeam'!C1:C200,""),IFERROR('_Import Miko VIPTeam'!D1:D200,"")),""), IFERROR('_Import Miko Book'!I1:K200,""); IFERROR(IF('_Import Concept Book'!B1:B200="","","Concept"),""), IFERROR('_Import Concept Book'!B1:F200,""), IFERROR(IFERROR('_Import Concept VIPTeam'!B1:B200,""),""), IFERROR(IF(IFERROR('_Import Concept VIPTeam'!C1:C200,"")<>"",IFERROR('_Import Concept VIPTeam'!C1:C200,""),IFERROR('_Import Concept VIPTeam'!D1:D200,"")),""), IFERROR('_Import Concept Book'!I1:K200,""); IFERROR(IF('_Import Daily Book'!B1:B200="","","Daily"),""), IFERROR('_Import Daily Book'!B1:F200,""), IFERROR(IFERROR('_Import Daily VIPTeam'!B1:B200,""),""), IFERROR(IF(IFERROR('_Import Daily VIPTeam'!C1:C200,"")<>"",IFERROR('_Import Daily VIPTeam'!C1:C200,""),IFERROR('_Import Daily VIPTeam'!D1:D200,"")),""), IFERROR('_Import Daily Book'!I1:K200,""); IFERROR(IF('_Import Prime Book'!B1:B200="","","Prime"),""), IFERROR('_Import Prime Book'!B1:F200,""), IFERROR(IFERROR('_Import Prime VIPTeam'!B1:B200,""),""), IFERROR(IF(IFERROR('_Import Prime VIPTeam'!C1:C200,"")<>"",IFERROR('_Import Prime VIPTeam'!C1:C200,""),IFERROR('_Import Prime VIPTeam'!D1:D200,"")),""), IFERROR('_Import Prime Book'!I1:K200,""); IFERROR(IF('_Import Yuri Book'!B1:B200="","","Yuri"),""), IFERROR('_Import Yuri Book'!B1:F200,""), IFERROR(IFERROR('_Import Yuri VIPTeam'!B1:B200,""),""), IFERROR(IF(IFERROR('_Import Yuri VIPTeam'!C1:C200,"")<>"",IFERROR('_Import Yuri VIPTeam'!C1:C200,""),IFERROR('_Import Yuri VIPTeam'!D1:D200,"")),""), IFERROR('_Import Yuri Book'!I1:K200,"")}, {IFERROR((('_Import Tuna Book'!E1:E200="VIP Transferred")+(IFERROR('_Import Tuna VIPTeam'!B1:B200,"")="Yes"))*('_Import Tuna Book'!B1:B200<>"")*('_Import Tuna Book'!D1:D200<>""),FALSE); IFERROR((('_Import Plat Book'!E1:E200="VIP Transferred")+(IFERROR('_Import Plat VIPTeam'!B1:B200,"")="Yes"))*('_Import Plat Book'!B1:B200<>"")*('_Import Plat Book'!D1:D200<>""),FALSE); IFERROR((('_Import Chella Book'!E1:E200="VIP Transferred")+(IFERROR('_Import Chella VIPTeam'!B1:B200,"")="Yes"))*('_Import Chella Book'!B1:B200<>"")*('_Import Chella Book'!D1:D200<>""),FALSE); IFERROR((('_Import Moneyheist Book'!E1:E200="VIP Transferred")+(IFERROR('_Import Moneyheist VIPTeam'!B1:B200,"")="Yes"))*('_Import Moneyheist Book'!B1:B200<>"")*('_Import Moneyheist Book'!D1:D200<>""),FALSE); IFERROR((('_Import Seb Book'!E1:E200="VIP Transferred")+(IFERROR('_Import Seb VIPTeam'!B1:B200,"")="Yes"))*('_Import Seb Book'!B1:B200<>"")*('_Import Seb Book'!D1:D200<>""),FALSE); IFERROR((('_Import Pricey Book'!E1:E200="VIP Transferred")+(IFERROR('_Import Pricey VIPTeam'!B1:B200,"")="Yes"))*('_Import Pricey Book'!B1:B200<>"")*('_Import Pricey Book'!D1:D200<>""),FALSE); IFERROR((('_Import Seanok Book'!E1:E200="VIP Transferred")+(IFERROR('_Import Seanok VIPTeam'!B1:B200,"")="Yes"))*('_Import Seanok Book'!B1:B200<>"")*('_Import Seanok Book'!D1:D200<>""),FALSE); IFERROR((('_Import Gwen Book'!E1:E200="VIP Transferred")+(IFERROR('_Import Gwen VIPTeam'!B1:B200,"")="Yes"))*('_Import Gwen Book'!B1:B200<>"")*('_Import Gwen Book'!D1:D200<>""),FALSE); IFERROR((('_Import Miko Book'!E1:E200="VIP Transferred")+(IFERROR('_Import Miko VIPTeam'!B1:B200,"")="Yes"))*('_Import Miko Book'!B1:B200<>"")*('_Import Miko Book'!D1:D200<>""),FALSE); IFERROR((('_Import Concept Book'!E1:E200="VIP Transferred")+(IFERROR('_Import Concept VIPTeam'!B1:B200,"")="Yes"))*('_Import Concept Book'!B1:B200<>"")*('_Import Concept Book'!D1:D200<>""),FALSE); IFERROR((('_Import Daily Book'!E1:E200="VIP Transferred")+(IFERROR('_Import Daily VIPTeam'!B1:B200,"")="Yes"))*('_Import Daily Book'!B1:B200<>"")*('_Import Daily Book'!D1:D200<>""),FALSE); IFERROR((('_Import Prime Book'!E1:E200="VIP Transferred")+(IFERROR('_Import Prime VIPTeam'!B1:B200,"")="Yes"))*('_Import Prime Book'!B1:B200<>"")*('_Import Prime Book'!D1:D200<>""),FALSE); IFERROR((('_Import Yuri Book'!E1:E200="VIP Transferred")+(IFERROR('_Import Yuri VIPTeam'!B1:B200,"")="Yes"))*('_Import Yuri Book'!B1:B200<>"")*('_Import Yuri Book'!D1:D200<>""),FALSE)}), ""), 8, FALSE)

Sheet Overdue Follow-Ups
A1: Overdue Follow-Ups - All Reps Combined
A2: Every lead, any rep, whose Next Follow-Up Due date has already passed and hasn't been acted on since. Read-only - go to that rep's own Daily Task to work it.
A4: Rep | B4: Player Handle | C4: Status | D4: Health | E4: Last Contact Date | F4: Next Follow-Up Due | G4: Next Action
A5: =IFERROR(FILTER({IF('_Import Tuna Book'!B1:B200="","","Tuna"), '_Import Tuna Book'!B1:B200, '_Import Tuna Book'!E1:F200, '_Import Tuna Book'!I1:K200; IF('_Import Plat Book'!B1:B200="","","Plat"), '_Import Plat Book'!B1:B200, '_Import Plat Book'!E1:F200, '_Import Plat Book'!I1:K200; IF('_Import Chella Book'!B1:B200="","","Chella"), '_Import Chella Book'!B1:B200, '_Import Chella Book'!E1:F200, '_Import Chella Book'!I1:K200; IF('_Import Moneyheist Book'!B1:B200="","","Moneyheist"), '_Import Moneyheist Book'!B1:B200, '_Import Moneyheist Book'!E1:F200, '_Import Moneyheist Book'!I1:K200; IF('_Import Seb Book'!B1:B200="","","Seb"), '_Import Seb Book'!B1:B200, '_Import Seb Book'!E1:F200, '_Import Seb Book'!I1:K200; IF('_Import Pricey Book'!B1:B200="","","Pricey"), '_Import Pricey Book'!B1:B200, '_Import Pricey Book'!E1:F200, '_Import Pricey Book'!I1:K200; IF('_Import Seanok Book'!B1:B200="","","Seanok"), '_Import Seanok Book'!B1:B200, '_Import Seanok Book'!E1:F200, '_Import Seanok Book'!I1:K200; IF('_Import Gwen Book'!B1:B200="","","Gwen"), '_Import Gwen Book'!B1:B200, '_Import Gwen Book'!E1:F200, '_Import Gwen Book'!I1:K200; IF('_Import Miko Book'!B1:B200="","","Miko"), '_Import Miko Book'!B1:B200, '_Import Miko Book'!E1:F200, '_Import Miko Book'!I1:K200; IF('_Import Concept Book'!B1:B200="","","Concept"), '_Import Concept Book'!B1:B200, '_Import Concept Book'!E1:F200, '_Import Concept Book'!I1:K200; IF('_Import Daily Book'!B1:B200="","","Daily"), '_Import Daily Book'!B1:B200, '_Import Daily Book'!E1:F200, '_Import Daily Book'!I1:K200; IF('_Import Prime Book'!B1:B200="","","Prime"), '_Import Prime Book'!B1:B200, '_Import Prime Book'!E1:F200, '_Import Prime Book'!I1:K200; IF('_Import Yuri Book'!B1:B200="","","Yuri"), '_Import Yuri Book'!B1:B200, '_Import Yuri Book'!E1:F200, '_Import Yuri Book'!I1:K200}, {(('_Import Tuna Book'!J1:J200<>"")*('_Import Tuna Book'!J1:J200<TODAY()))>0; (('_Import Plat Book'!J1:J200<>"")*('_Import Plat Book'!J1:J200<TODAY()))>0; (('_Import Chella Book'!J1:J200<>"")*('_Import Chella Book'!J1:J200<TODAY()))>0; (('_Import Moneyheist Book'!J1:J200<>"")*('_Import Moneyheist Book'!J1:J200<TODAY()))>0; (('_Import Seb Book'!J1:J200<>"")*('_Import Seb Book'!J1:J200<TODAY()))>0; (('_Import Pricey Book'!J1:J200<>"")*('_Import Pricey Book'!J1:J200<TODAY()))>0; (('_Import Seanok Book'!J1:J200<>"")*('_Import Seanok Book'!J1:J200<TODAY()))>0; (('_Import Gwen Book'!J1:J200<>"")*('_Import Gwen Book'!J1:J200<TODAY()))>0; (('_Import Miko Book'!J1:J200<>"")*('_Import Miko Book'!J1:J200<TODAY()))>0; (('_Import Concept Book'!J1:J200<>"")*('_Import Concept Book'!J1:J200<TODAY()))>0; (('_Import Daily Book'!J1:J200<>"")*('_Import Daily Book'!J1:J200<TODAY()))>0; (('_Import Prime Book'!J1:J200<>"")*('_Import Prime Book'!J1:J200<TODAY()))>0; (('_Import Yuri Book'!J1:J200<>"")*('_Import Yuri Book'!J1:J200<TODAY()))>0}), "")

Sheet Executive Dashboard
A1: Executive Dashboard - Team Overview
A2: Live-pulled from each rep's Activity Log. Read-only - nothing to edit here.
A4: VIP Transfers | D4: FTD's
A5: This Week | B5: =SUM(C28:C40) | D5: This Week | E5: =SUM(D28:D40)
A6: This Month | B6: =SUM(F28:F40) | D6: This Month | E6: =SUM(G28:G40)
A7: All Time | B7: =COUNTIF('_Import Tuna ActivityLog'!$C$1:$C$5000,"VIP Transfer")+COUNTIF('_Import Tuna ActivityLog'!$C$1:$C$5000,"*-> VIP Transferred")+COUNTIF('_Import Plat ActivityLog'!$C$1:$C$5000,"VIP Transfer")+COUNTIF('_Import Plat ActivityLog'!$C$1:$C$5000,"*-> VIP Transferred")+COUNTIF('_Import Chella ActivityLog'!$C$1:$C$5000,"VIP Transfer")+COUNTIF('_Import Chella ActivityLog'!$C$1:$C$5000,"*-> VIP Transferred")+COUNTIF('_Import Moneyheist ActivityLog'!$C$1:$C$5000,"VIP Transfer")+COUNTIF('_Import Moneyheist ActivityLog'!$C$1:$C$5000,"*-> VIP Transferred")+COUNTIF('_Import Seb ActivityLog'!$C$1:$C$5000,"VIP Transfer")+COUNTIF('_Import Seb ActivityLog'!$C$1:$C$5000,"*-> VIP Transferred")+COUNTIF('_Import Pricey ActivityLog'!$C$1:$C$5000,"VIP Transfer")+COUNTIF('_Import Pricey ActivityLog'!$C$1:$C$5000,"*-> VIP Transferred")+COUNTIF('_Import Seanok ActivityLog'!$C$1:$C$5000,"VIP Transfer")+COUNTIF('_Import Seanok ActivityLog'!$C$1:$C$5000,"*-> VIP Transferred")+COUNTIF('_Import Gwen ActivityLog'!$C$1:$C$5000,"VIP Transfer")+COUNTIF('_Import Gwen ActivityLog'!$C$1:$C$5000,"*-> VIP Transferred")+COUNTIF('_Import Miko ActivityLog'!$C$1:$C$5000,"VIP Transfer")+COUNTIF('_Import Miko ActivityLog'!$C$1:$C$5000,"*-> VIP Transferred")+COUNTIF('_Import Concept ActivityLog'!$C$1:$C$5000,"VIP Transfer")+COUNTIF('_Import Concept ActivityLog'!$C$1:$C$5000,"*-> VIP Transferred")+COUNTIF('_Import Daily ActivityLog'!$C$1:$C$5000,"VIP Transfer")+COUNTIF('_Import Daily ActivityLog'!$C$1:$C$5000,"*-> VIP Transferred")+COUNTIF('_Import Prime ActivityLog'!$C$1:$C$5000,"VIP Transfer")+COUNTIF('_Import Prime ActivityLog'!$C$1:$C$5000,"*-> VIP Transferred")+COUNTIF('_Import Yuri ActivityLog'!$C$1:$C$5000,"VIP Transfer")+COUNTIF('_Import Yuri ActivityLog'!$C$1:$C$5000,"*-> VIP Transferred") | D7: All Time | E7: =COUNTIF('_Import Tuna ActivityLog'!$C$1:$C$5000,"*-> First Deposit")+COUNTIF('_Import Plat ActivityLog'!$C$1:$C$5000,"*-> First Deposit")+COUNTIF('_Import Chella ActivityLog'!$C$1:$C$5000,"*-> First Deposit")+COUNTIF('_Import Moneyheist ActivityLog'!$C$1:$C$5000,"*-> First Deposit")+COUNTIF('_Import Seb ActivityLog'!$C$1:$C$5000,"*-> First Deposit")+COUNTIF('_Import Pricey ActivityLog'!$C$1:$C$5000,"*-> First Deposit")+COUNTIF('_Import Seanok ActivityLog'!$C$1:$C$5000,"*-> First Deposit")+COUNTIF('_Import Gwen ActivityLog'!$C$1:$C$5000,"*-> First Deposit")+COUNTIF('_Import Miko ActivityLog'!$C$1:$C$5000,"*-> First Deposit")+COUNTIF('_Import Concept ActivityLog'!$C$1:$C$5000,"*-> First Deposit")+COUNTIF('_Import Daily ActivityLog'!$C$1:$C$5000,"*-> First Deposit")+COUNTIF('_Import Prime ActivityLog'!$C$1:$C$5000,"*-> First Deposit")+COUNTIF('_Import Yuri ActivityLog'!$C$1:$C$5000,"*-> First Deposit")
A9: Today vs. Target
A10: Rep | B10: Active Leads Today | C10: Active Leads Target | D10: VIP Transfers Today | E10: VIP Transfers Target | F10: FTD Today | G10: FTD Target
A11: Tuna | B11: =COUNTIFS('_Import Tuna Book'!$H$1:$H$200,TODAY(),'_Import Tuna Book'!$E$1:$E$200,"<>Dead Lead",'_Import Tuna Book'!$E$1:$E$200,"<>Potential Lead") | C11: =IFERROR(INDEX('Team & KPI Targets'!$E$5:$E$17,MATCH("Tuna",'Team & KPI Targets'!$A$5:$A$17,0)),"TBD") | D11: =COUNTIFS('_Import Tuna ActivityLog'!$A$1:$A$5000,TODAY(),'_Import Tuna ActivityLog'!$C$1:$C$5000,"VIP Transfer")+COUNTIFS('_Import Tuna ActivityLog'!$A$1:$A$5000,TODAY(),'_Import Tuna ActivityLog'!$C$1:$C$5000,"*-> VIP Transferred") | E11: =IFERROR(INDEX('Team & KPI Targets'!$F$5:$F$17,MATCH("Tuna",'Team & KPI Targets'!$A$5:$A$17,0)),"TBD") | F11: =COUNTIFS('_Import Tuna ActivityLog'!$A$1:$A$5000,TODAY(),'_Import Tuna ActivityLog'!$C$1:$C$5000,"*-> First Deposit") | G11: =IFERROR(INDEX('Team & KPI Targets'!$G$5:$G$17,MATCH("Tuna",'Team & KPI Targets'!$A$5:$A$17,0)),"TBD")
A12: Plat | B12: =COUNTIFS('_Import Plat Book'!$H$1:$H$200,TODAY(),'_Import Plat Book'!$E$1:$E$200,"<>Dead Lead",'_Import Plat Book'!$E$1:$E$200,"<>Potential Lead") | C12: =IFERROR(INDEX('Team & KPI Targets'!$E$5:$E$17,MATCH("Plat",'Team & KPI Targets'!$A$5:$A$17,0)),"TBD") | D12: =COUNTIFS('_Import Plat ActivityLog'!$A$1:$A$5000,TODAY(),'_Import Plat ActivityLog'!$C$1:$C$5000,"VIP Transfer")+COUNTIFS('_Import Plat ActivityLog'!$A$1:$A$5000,TODAY(),'_Import Plat ActivityLog'!$C$1:$C$5000,"*-> VIP Transferred") | E12: =IFERROR(INDEX('Team & KPI Targets'!$F$5:$F$17,MATCH("Plat",'Team & KPI Targets'!$A$5:$A$17,0)),"TBD") | F12: =COUNTIFS('_Import Plat ActivityLog'!$A$1:$A$5000,TODAY(),'_Import Plat ActivityLog'!$C$1:$C$5000,"*-> First Deposit") | G12: =IFERROR(INDEX('Team & KPI Targets'!$G$5:$G$17,MATCH("Plat",'Team & KPI Targets'!$A$5:$A$17,0)),"TBD")
A13: Chella | B13: =COUNTIFS('_Import Chella Book'!$H$1:$H$200,TODAY(),'_Import Chella Book'!$E$1:$E$200,"<>Dead Lead",'_Import Chella Book'!$E$1:$E$200,"<>Potential Lead") | C13: =IFERROR(INDEX('Team & KPI Targets'!$E$5:$E$17,MATCH("Chella",'Team & KPI Targets'!$A$5:$A$17,0)),"TBD") | D13: =COUNTIFS('_Import Chella ActivityLog'!$A$1:$A$5000,TODAY(),'_Import Chella ActivityLog'!$C$1:$C$5000,"VIP Transfer")+COUNTIFS('_Import Chella ActivityLog'!$A$1:$A$5000,TODAY(),'_Import Chella ActivityLog'!$C$1:$C$5000,"*-> VIP Transferred") | E13: =IFERROR(INDEX('Team & KPI Targets'!$F$5:$F$17,MATCH("Chella",'Team & KPI Targets'!$A$5:$A$17,0)),"TBD") | F13: =COUNTIFS('_Import Chella ActivityLog'!$A$1:$A$5000,TODAY(),'_Import Chella ActivityLog'!$C$1:$C$5000,"*-> First Deposit") | G13: =IFERROR(INDEX('Team & KPI Targets'!$G$5:$G$17,MATCH("Chella",'Team & KPI Targets'!$A$5:$A$17,0)),"TBD")
A14: Moneyheist | B14: =COUNTIFS('_Import Moneyheist Book'!$H$1:$H$200,TODAY(),'_Import Moneyheist Book'!$E$1:$E$200,"<>Dead Lead",'_Import Moneyheist Book'!$E$1:$E$200,"<>Potential Lead") | C14: =IFERROR(INDEX('Team & KPI Targets'!$E$5:$E$17,MATCH("Moneyheist",'Team & KPI Targets'!$A$5:$A$17,0)),"TBD") | D14: =COUNTIFS('_Import Moneyheist ActivityLog'!$A$1:$A$5000,TODAY(),'_Import Moneyheist ActivityLog'!$C$1:$C$5000,"VIP Transfer")+COUNTIFS('_Import Moneyheist ActivityLog'!$A$1:$A$5000,TODAY(),'_Import Moneyheist ActivityLog'!$C$1:$C$5000,"*-> VIP Transferred") | E14: =IFERROR(INDEX('Team & KPI Targets'!$F$5:$F$17,MATCH("Moneyheist",'Team & KPI Targets'!$A$5:$A$17,0)),"TBD") | F14: =COUNTIFS('_Import Moneyheist ActivityLog'!$A$1:$A$5000,TODAY(),'_Import Moneyheist ActivityLog'!$C$1:$C$5000,"*-> First Deposit") | G14: =IFERROR(INDEX('Team & KPI Targets'!$G$5:$G$17,MATCH("Moneyheist",'Team & KPI Targets'!$A$5:$A$17,0)),"TBD")
A15: Seb | B15: =COUNTIFS('_Import Seb Book'!$H$1:$H$200,TODAY(),'_Import Seb Book'!$E$1:$E$200,"<>Dead Lead",'_Import Seb Book'!$E$1:$E$200,"<>Potential Lead") | C15: =IFERROR(INDEX('Team & KPI Targets'!$E$5:$E$17,MATCH("Seb",'Team & KPI Targets'!$A$5:$A$17,0)),"TBD") | D15: =COUNTIFS('_Import Seb ActivityLog'!$A$1:$A$5000,TODAY(),'_Import Seb ActivityLog'!$C$1:$C$5000,"VIP Transfer")+COUNTIFS('_Import Seb ActivityLog'!$A$1:$A$5000,TODAY(),'_Import Seb ActivityLog'!$C$1:$C$5000,"*-> VIP Transferred") | E15: =IFERROR(INDEX('Team & KPI Targets'!$F$5:$F$17,MATCH("Seb",'Team & KPI Targets'!$A$5:$A$17,0)),"TBD") | F15: =COUNTIFS('_Import Seb ActivityLog'!$A$1:$A$5000,TODAY(),'_Import Seb ActivityLog'!$C$1:$C$5000,"*-> First Deposit") | G15: =IFERROR(INDEX('Team & KPI Targets'!$G$5:$G$17,MATCH("Seb",'Team & KPI Targets'!$A$5:$A$17,0)),"TBD")
A16: Pricey | B16: =COUNTIFS('_Import Pricey Book'!$H$1:$H$200,TODAY(),'_Import Pricey Book'!$E$1:$E$200,"<>Dead Lead",'_Import Pricey Book'!$E$1:$E$200,"<>Potential Lead") | C16: =IFERROR(INDEX('Team & KPI Targets'!$E$5:$E$17,MATCH("Pricey",'Team & KPI Targets'!$A$5:$A$17,0)),"TBD") | D16: =COUNTIFS('_Import Pricey ActivityLog'!$A$1:$A$5000,TODAY(),'_Import Pricey ActivityLog'!$C$1:$C$5000,"VIP Transfer")+COUNTIFS('_Import Pricey ActivityLog'!$A$1:$A$5000,TODAY(),'_Import Pricey ActivityLog'!$C$1:$C$5000,"*-> VIP Transferred") | E16: =IFERROR(INDEX('Team & KPI Targets'!$F$5:$F$17,MATCH("Pricey",'Team & KPI Targets'!$A$5:$A$17,0)),"TBD") | F16: =COUNTIFS('_Import Pricey ActivityLog'!$A$1:$A$5000,TODAY(),'_Import Pricey ActivityLog'!$C$1:$C$5000,"*-> First Deposit") | G16: =IFERROR(INDEX('Team & KPI Targets'!$G$5:$G$17,MATCH("Pricey",'Team & KPI Targets'!$A$5:$A$17,0)),"TBD")
A17: Seanok | B17: =COUNTIFS('_Import Seanok Book'!$H$1:$H$200,TODAY(),'_Import Seanok Book'!$E$1:$E$200,"<>Dead Lead",'_Import Seanok Book'!$E$1:$E$200,"<>Potential Lead") | C17: =IFERROR(INDEX('Team & KPI Targets'!$E$5:$E$17,MATCH("Seanok",'Team & KPI Targets'!$A$5:$A$17,0)),"TBD") | D17: =COUNTIFS('_Import Seanok ActivityLog'!$A$1:$A$5000,TODAY(),'_Import Seanok ActivityLog'!$C$1:$C$5000,"VIP Transfer")+COUNTIFS('_Import Seanok ActivityLog'!$A$1:$A$5000,TODAY(),'_Import Seanok ActivityLog'!$C$1:$C$5000,"*-> VIP Transferred") | E17: =IFERROR(INDEX('Team & KPI Targets'!$F$5:$F$17,MATCH("Seanok",'Team & KPI Targets'!$A$5:$A$17,0)),"TBD") | F17: =COUNTIFS('_Import Seanok ActivityLog'!$A$1:$A$5000,TODAY(),'_Import Seanok ActivityLog'!$C$1:$C$5000,"*-> First Deposit") | G17: =IFERROR(INDEX('Team & KPI Targets'!$G$5:$G$17,MATCH("Seanok",'Team & KPI Targets'!$A$5:$A$17,0)),"TBD")
A18: Gwen | B18: =COUNTIFS('_Import Gwen Book'!$H$1:$H$200,TODAY(),'_Import Gwen Book'!$E$1:$E$200,"<>Dead Lead",'_Import Gwen Book'!$E$1:$E$200,"<>Potential Lead") | C18: =IFERROR(INDEX('Team & KPI Targets'!$E$5:$E$17,MATCH("Gwen",'Team & KPI Targets'!$A$5:$A$17,0)),"TBD") | D18: =COUNTIFS('_Import Gwen ActivityLog'!$A$1:$A$5000,TODAY(),'_Import Gwen ActivityLog'!$C$1:$C$5000,"VIP Transfer")+COUNTIFS('_Import Gwen ActivityLog'!$A$1:$A$5000,TODAY(),'_Import Gwen ActivityLog'!$C$1:$C$5000,"*-> VIP Transferred") | E18: =IFERROR(INDEX('Team & KPI Targets'!$F$5:$F$17,MATCH("Gwen",'Team & KPI Targets'!$A$5:$A$17,0)),"TBD") | F18: =COUNTIFS('_Import Gwen ActivityLog'!$A$1:$A$5000,TODAY(),'_Import Gwen ActivityLog'!$C$1:$C$5000,"*-> First Deposit") | G18: =IFERROR(INDEX('Team & KPI Targets'!$G$5:$G$17,MATCH("Gwen",'Team & KPI Targets'!$A$5:$A$17,0)),"TBD")
A19: Miko | B19: =COUNTIFS('_Import Miko Book'!$H$1:$H$200,TODAY(),'_Import Miko Book'!$E$1:$E$200,"<>Dead Lead",'_Import Miko Book'!$E$1:$E$200,"<>Potential Lead") | C19: =IFERROR(INDEX('Team & KPI Targets'!$E$5:$E$17,MATCH("Miko",'Team & KPI Targets'!$A$5:$A$17,0)),"TBD") | D19: =COUNTIFS('_Import Miko ActivityLog'!$A$1:$A$5000,TODAY(),'_Import Miko ActivityLog'!$C$1:$C$5000,"VIP Transfer")+COUNTIFS('_Import Miko ActivityLog'!$A$1:$A$5000,TODAY(),'_Import Miko ActivityLog'!$C$1:$C$5000,"*-> VIP Transferred") | E19: =IFERROR(INDEX('Team & KPI Targets'!$F$5:$F$17,MATCH("Miko",'Team & KPI Targets'!$A$5:$A$17,0)),"TBD") | F19: =COUNTIFS('_Import Miko ActivityLog'!$A$1:$A$5000,TODAY(),'_Import Miko ActivityLog'!$C$1:$C$5000,"*-> First Deposit") | G19: =IFERROR(INDEX('Team & KPI Targets'!$G$5:$G$17,MATCH("Miko",'Team & KPI Targets'!$A$5:$A$17,0)),"TBD")
A20: Concept | B20: =COUNTIFS('_Import Concept Book'!$H$1:$H$200,TODAY(),'_Import Concept Book'!$E$1:$E$200,"<>Dead Lead",'_Import Concept Book'!$E$1:$E$200,"<>Potential Lead") | C20: =IFERROR(INDEX('Team & KPI Targets'!$E$5:$E$17,MATCH("Concept",'Team & KPI Targets'!$A$5:$A$17,0)),"TBD") | D20: =COUNTIFS('_Import Concept ActivityLog'!$A$1:$A$5000,TODAY(),'_Import Concept ActivityLog'!$C$1:$C$5000,"VIP Transfer")+COUNTIFS('_Import Concept ActivityLog'!$A$1:$A$5000,TODAY(),'_Import Concept ActivityLog'!$C$1:$C$5000,"*-> VIP Transferred") | E20: =IFERROR(INDEX('Team & KPI Targets'!$F$5:$F$17,MATCH("Concept",'Team & KPI Targets'!$A$5:$A$17,0)),"TBD") | F20: =COUNTIFS('_Import Concept ActivityLog'!$A$1:$A$5000,TODAY(),'_Import Concept ActivityLog'!$C$1:$C$5000,"*-> First Deposit") | G20: =IFERROR(INDEX('Team & KPI Targets'!$G$5:$G$17,MATCH("Concept",'Team & KPI Targets'!$A$5:$A$17,0)),"TBD")
A21: Daily | B21: =COUNTIFS('_Import Daily Book'!$H$1:$H$200,TODAY(),'_Import Daily Book'!$E$1:$E$200,"<>Dead Lead",'_Import Daily Book'!$E$1:$E$200,"<>Potential Lead") | C21: =IFERROR(INDEX('Team & KPI Targets'!$E$5:$E$17,MATCH("Daily",'Team & KPI Targets'!$A$5:$A$17,0)),"TBD") | D21: =COUNTIFS('_Import Daily ActivityLog'!$A$1:$A$5000,TODAY(),'_Import Daily ActivityLog'!$C$1:$C$5000,"VIP Transfer")+COUNTIFS('_Import Daily ActivityLog'!$A$1:$A$5000,TODAY(),'_Import Daily ActivityLog'!$C$1:$C$5000,"*-> VIP Transferred") | E21: =IFERROR(INDEX('Team & KPI Targets'!$F$5:$F$17,MATCH("Daily",'Team & KPI Targets'!$A$5:$A$17,0)),"TBD") | F21: =COUNTIFS('_Import Daily ActivityLog'!$A$1:$A$5000,TODAY(),'_Import Daily ActivityLog'!$C$1:$C$5000,"*-> First Deposit") | G21: =IFERROR(INDEX('Team & KPI Targets'!$G$5:$G$17,MATCH("Daily",'Team & KPI Targets'!$A$5:$A$17,0)),"TBD")
A22: Prime | B22: =COUNTIFS('_Import Prime Book'!$H$1:$H$200,TODAY(),'_Import Prime Book'!$E$1:$E$200,"<>Dead Lead",'_Import Prime Book'!$E$1:$E$200,"<>Potential Lead") | C22: =IFERROR(INDEX('Team & KPI Targets'!$E$5:$E$17,MATCH("Prime",'Team & KPI Targets'!$A$5:$A$17,0)),"TBD") | D22: =COUNTIFS('_Import Prime ActivityLog'!$A$1:$A$5000,TODAY(),'_Import Prime ActivityLog'!$C$1:$C$5000,"VIP Transfer")+COUNTIFS('_Import Prime ActivityLog'!$A$1:$A$5000,TODAY(),'_Import Prime ActivityLog'!$C$1:$C$5000,"*-> VIP Transferred") | E22: =IFERROR(INDEX('Team & KPI Targets'!$F$5:$F$17,MATCH("Prime",'Team & KPI Targets'!$A$5:$A$17,0)),"TBD") | F22: =COUNTIFS('_Import Prime ActivityLog'!$A$1:$A$5000,TODAY(),'_Import Prime ActivityLog'!$C$1:$C$5000,"*-> First Deposit") | G22: =IFERROR(INDEX('Team & KPI Targets'!$G$5:$G$17,MATCH("Prime",'Team & KPI Targets'!$A$5:$A$17,0)),"TBD")
A23: Yuri | B23: =COUNTIFS('_Import Yuri Book'!$H$1:$H$200,TODAY(),'_Import Yuri Book'!$E$1:$E$200,"<>Dead Lead",'_Import Yuri Book'!$E$1:$E$200,"<>Potential Lead") | C23: =IFERROR(INDEX('Team & KPI Targets'!$E$5:$E$17,MATCH("Yuri",'Team & KPI Targets'!$A$5:$A$17,0)),"TBD") | D23: =COUNTIFS('_Import Yuri ActivityLog'!$A$1:$A$5000,TODAY(),'_Import Yuri ActivityLog'!$C$1:$C$5000,"VIP Transfer")+COUNTIFS('_Import Yuri ActivityLog'!$A$1:$A$5000,TODAY(),'_Import Yuri ActivityLog'!$C$1:$C$5000,"*-> VIP Transferred") | E23: =IFERROR(INDEX('Team & KPI Targets'!$F$5:$F$17,MATCH("Yuri",'Team & KPI Targets'!$A$5:$A$17,0)),"TBD") | F23: =COUNTIFS('_Import Yuri ActivityLog'!$A$1:$A$5000,TODAY(),'_Import Yuri ActivityLog'!$C$1:$C$5000,"*-> First Deposit") | G23: =IFERROR(INDEX('Team & KPI Targets'!$G$5:$G$17,MATCH("Yuri",'Team & KPI Targets'!$A$5:$A$17,0)),"TBD")
A24: COMPANY TOTAL | B24: =SUM(B11:B23) | C24: =SUM(C11:C23) | D24: =SUM(D11:D23) | E24: =SUM(E11:E23) | F24: =SUM(F11:F23) | G24: =SUM(G11:G23)
A26: This Week / This Month
A27: Rep | B27: Active Leads (Week) | C27: VIP Transfers (Week) | D27: FTD (Week) | E27: Active Leads (Month) | F27: VIP Transfers (Month) | G27: FTD (Month)
A28: Tuna | B28: =COUNTIFS('_Import Tuna Book'!$H$1:$H$200,">="&(TODAY()-WEEKDAY(TODAY(),3)),'_Import Tuna Book'!$H$1:$H$200,"<="&TODAY(),'_Import Tuna Book'!$E$1:$E$200,"<>Dead Lead",'_Import Tuna Book'!$E$1:$E$200,"<>Potential Lead") | C28: =COUNTIFS('_Import Tuna ActivityLog'!$A$1:$A$5000,">="&(TODAY()-WEEKDAY(TODAY(),3)),'_Import Tuna ActivityLog'!$A$1:$A$5000,"<="&TODAY(),'_Import Tuna ActivityLog'!$C$1:$C$5000,"VIP Transfer")+COUNTIFS('_Import Tuna ActivityLog'!$A$1:$A$5000,">="&(TODAY()-WEEKDAY(TODAY(),3)),'_Import Tuna ActivityLog'!$A$1:$A$5000,"<="&TODAY(),'_Import Tuna ActivityLog'!$C$1:$C$5000,"*-> VIP Transferred") | D28: =COUNTIFS('_Import Tuna ActivityLog'!$A$1:$A$5000,">="&(TODAY()-WEEKDAY(TODAY(),3)),'_Import Tuna ActivityLog'!$A$1:$A$5000,"<="&TODAY(),'_Import Tuna ActivityLog'!$C$1:$C$5000,"*-> First Deposit") | E28: =COUNTIFS('_Import Tuna Book'!$H$1:$H$200,">="&DATE(YEAR(TODAY()),MONTH(TODAY()),1),'_Import Tuna Book'!$H$1:$H$200,"<="&TODAY(),'_Import Tuna Book'!$E$1:$E$200,"<>Dead Lead",'_Import Tuna Book'!$E$1:$E$200,"<>Potential Lead") | F28: =COUNTIFS('_Import Tuna ActivityLog'!$A$1:$A$5000,">="&DATE(YEAR(TODAY()),MONTH(TODAY()),1),'_Import Tuna ActivityLog'!$A$1:$A$5000,"<="&TODAY(),'_Import Tuna ActivityLog'!$C$1:$C$5000,"VIP Transfer")+COUNTIFS('_Import Tuna ActivityLog'!$A$1:$A$5000,">="&DATE(YEAR(TODAY()),MONTH(TODAY()),1),'_Import Tuna ActivityLog'!$A$1:$A$5000,"<="&TODAY(),'_Import Tuna ActivityLog'!$C$1:$C$5000,"*-> VIP Transferred") | G28: =COUNTIFS('_Import Tuna ActivityLog'!$A$1:$A$5000,">="&DATE(YEAR(TODAY()),MONTH(TODAY()),1),'_Import Tuna ActivityLog'!$A$1:$A$5000,"<="&TODAY(),'_Import Tuna ActivityLog'!$C$1:$C$5000,"*-> First Deposit")
A29: Plat | B29: =COUNTIFS('_Import Plat Book'!$H$1:$H$200,">="&(TODAY()-WEEKDAY(TODAY(),3)),'_Import Plat Book'!$H$1:$H$200,"<="&TODAY(),'_Import Plat Book'!$E$1:$E$200,"<>Dead Lead",'_Import Plat Book'!$E$1:$E$200,"<>Potential Lead") | C29: =COUNTIFS('_Import Plat ActivityLog'!$A$1:$A$5000,">="&(TODAY()-WEEKDAY(TODAY(),3)),'_Import Plat ActivityLog'!$A$1:$A$5000,"<="&TODAY(),'_Import Plat ActivityLog'!$C$1:$C$5000,"VIP Transfer")+COUNTIFS('_Import Plat ActivityLog'!$A$1:$A$5000,">="&(TODAY()-WEEKDAY(TODAY(),3)),'_Import Plat ActivityLog'!$A$1:$A$5000,"<="&TODAY(),'_Import Plat ActivityLog'!$C$1:$C$5000,"*-> VIP Transferred") | D29: =COUNTIFS('_Import Plat ActivityLog'!$A$1:$A$5000,">="&(TODAY()-WEEKDAY(TODAY(),3)),'_Import Plat ActivityLog'!$A$1:$A$5000,"<="&TODAY(),'_Import Plat ActivityLog'!$C$1:$C$5000,"*-> First Deposit") | E29: =COUNTIFS('_Import Plat Book'!$H$1:$H$200,">="&DATE(YEAR(TODAY()),MONTH(TODAY()),1),'_Import Plat Book'!$H$1:$H$200,"<="&TODAY(),'_Import Plat Book'!$E$1:$E$200,"<>Dead Lead",'_Import Plat Book'!$E$1:$E$200,"<>Potential Lead") | F29: =COUNTIFS('_Import Plat ActivityLog'!$A$1:$A$5000,">="&DATE(YEAR(TODAY()),MONTH(TODAY()),1),'_Import Plat ActivityLog'!$A$1:$A$5000,"<="&TODAY(),'_Import Plat ActivityLog'!$C$1:$C$5000,"VIP Transfer")+COUNTIFS('_Import Plat ActivityLog'!$A$1:$A$5000,">="&DATE(YEAR(TODAY()),MONTH(TODAY()),1),'_Import Plat ActivityLog'!$A$1:$A$5000,"<="&TODAY(),'_Import Plat ActivityLog'!$C$1:$C$5000,"*-> VIP Transferred") | G29: =COUNTIFS('_Import Plat ActivityLog'!$A$1:$A$5000,">="&DATE(YEAR(TODAY()),MONTH(TODAY()),1),'_Import Plat ActivityLog'!$A$1:$A$5000,"<="&TODAY(),'_Import Plat ActivityLog'!$C$1:$C$5000,"*-> First Deposit")
A30: Chella | B30: =COUNTIFS('_Import Chella Book'!$H$1:$H$200,">="&(TODAY()-WEEKDAY(TODAY(),3)),'_Import Chella Book'!$H$1:$H$200,"<="&TODAY(),'_Import Chella Book'!$E$1:$E$200,"<>Dead Lead",'_Import Chella Book'!$E$1:$E$200,"<>Potential Lead") | C30: =COUNTIFS('_Import Chella ActivityLog'!$A$1:$A$5000,">="&(TODAY()-WEEKDAY(TODAY(),3)),'_Import Chella ActivityLog'!$A$1:$A$5000,"<="&TODAY(),'_Import Chella ActivityLog'!$C$1:$C$5000,"VIP Transfer")+COUNTIFS('_Import Chella ActivityLog'!$A$1:$A$5000,">="&(TODAY()-WEEKDAY(TODAY(),3)),'_Import Chella ActivityLog'!$A$1:$A$5000,"<="&TODAY(),'_Import Chella ActivityLog'!$C$1:$C$5000,"*-> VIP Transferred") | D30: =COUNTIFS('_Import Chella ActivityLog'!$A$1:$A$5000,">="&(TODAY()-WEEKDAY(TODAY(),3)),'_Import Chella ActivityLog'!$A$1:$A$5000,"<="&TODAY(),'_Import Chella ActivityLog'!$C$1:$C$5000,"*-> First Deposit") | E30: =COUNTIFS('_Import Chella Book'!$H$1:$H$200,">="&DATE(YEAR(TODAY()),MONTH(TODAY()),1),'_Import Chella Book'!$H$1:$H$200,"<="&TODAY(),'_Import Chella Book'!$E$1:$E$200,"<>Dead Lead",'_Import Chella Book'!$E$1:$E$200,"<>Potential Lead") | F30: =COUNTIFS('_Import Chella ActivityLog'!$A$1:$A$5000,">="&DATE(YEAR(TODAY()),MONTH(TODAY()),1),'_Import Chella ActivityLog'!$A$1:$A$5000,"<="&TODAY(),'_Import Chella ActivityLog'!$C$1:$C$5000,"VIP Transfer")+COUNTIFS('_Import Chella ActivityLog'!$A$1:$A$5000,">="&DATE(YEAR(TODAY()),MONTH(TODAY()),1),'_Import Chella ActivityLog'!$A$1:$A$5000,"<="&TODAY(),'_Import Chella ActivityLog'!$C$1:$C$5000,"*-> VIP Transferred") | G30: =COUNTIFS('_Import Chella ActivityLog'!$A$1:$A$5000,">="&DATE(YEAR(TODAY()),MONTH(TODAY()),1),'_Import Chella ActivityLog'!$A$1:$A$5000,"<="&TODAY(),'_Import Chella ActivityLog'!$C$1:$C$5000,"*-> First Deposit")
A31: Moneyheist | B31: =COUNTIFS('_Import Moneyheist Book'!$H$1:$H$200,">="&(TODAY()-WEEKDAY(TODAY(),3)),'_Import Moneyheist Book'!$H$1:$H$200,"<="&TODAY(),'_Import Moneyheist Book'!$E$1:$E$200,"<>Dead Lead",'_Import Moneyheist Book'!$E$1:$E$200,"<>Potential Lead") | C31: =COUNTIFS('_Import Moneyheist ActivityLog'!$A$1:$A$5000,">="&(TODAY()-WEEKDAY(TODAY(),3)),'_Import Moneyheist ActivityLog'!$A$1:$A$5000,"<="&TODAY(),'_Import Moneyheist ActivityLog'!$C$1:$C$5000,"VIP Transfer")+COUNTIFS('_Import Moneyheist ActivityLog'!$A$1:$A$5000,">="&(TODAY()-WEEKDAY(TODAY(),3)),'_Import Moneyheist ActivityLog'!$A$1:$A$5000,"<="&TODAY(),'_Import Moneyheist ActivityLog'!$C$1:$C$5000,"*-> VIP Transferred") | D31: =COUNTIFS('_Import Moneyheist ActivityLog'!$A$1:$A$5000,">="&(TODAY()-WEEKDAY(TODAY(),3)),'_Import Moneyheist ActivityLog'!$A$1:$A$5000,"<="&TODAY(),'_Import Moneyheist ActivityLog'!$C$1:$C$5000,"*-> First Deposit") | E31: =COUNTIFS('_Import Moneyheist Book'!$H$1:$H$200,">="&DATE(YEAR(TODAY()),MONTH(TODAY()),1),'_Import Moneyheist Book'!$H$1:$H$200,"<="&TODAY(),'_Import Moneyheist Book'!$E$1:$E$200,"<>Dead Lead",'_Import Moneyheist Book'!$E$1:$E$200,"<>Potential Lead") | F31: =COUNTIFS('_Import Moneyheist ActivityLog'!$A$1:$A$5000,">="&DATE(YEAR(TODAY()),MONTH(TODAY()),1),'_Import Moneyheist ActivityLog'!$A$1:$A$5000,"<="&TODAY(),'_Import Moneyheist ActivityLog'!$C$1:$C$5000,"VIP Transfer")+COUNTIFS('_Import Moneyheist ActivityLog'!$A$1:$A$5000,">="&DATE(YEAR(TODAY()),MONTH(TODAY()),1),'_Import Moneyheist ActivityLog'!$A$1:$A$5000,"<="&TODAY(),'_Import Moneyheist ActivityLog'!$C$1:$C$5000,"*-> VIP Transferred") | G31: =COUNTIFS('_Import Moneyheist ActivityLog'!$A$1:$A$5000,">="&DATE(YEAR(TODAY()),MONTH(TODAY()),1),'_Import Moneyheist ActivityLog'!$A$1:$A$5000,"<="&TODAY(),'_Import Moneyheist ActivityLog'!$C$1:$C$5000,"*-> First Deposit")
A32: Seb | B32: =COUNTIFS('_Import Seb Book'!$H$1:$H$200,">="&(TODAY()-WEEKDAY(TODAY(),3)),'_Import Seb Book'!$H$1:$H$200,"<="&TODAY(),'_Import Seb Book'!$E$1:$E$200,"<>Dead Lead",'_Import Seb Book'!$E$1:$E$200,"<>Potential Lead") | C32: =COUNTIFS('_Import Seb ActivityLog'!$A$1:$A$5000,">="&(TODAY()-WEEKDAY(TODAY(),3)),'_Import Seb ActivityLog'!$A$1:$A$5000,"<="&TODAY(),'_Import Seb ActivityLog'!$C$1:$C$5000,"VIP Transfer")+COUNTIFS('_Import Seb ActivityLog'!$A$1:$A$5000,">="&(TODAY()-WEEKDAY(TODAY(),3)),'_Import Seb ActivityLog'!$A$1:$A$5000,"<="&TODAY(),'_Import Seb ActivityLog'!$C$1:$C$5000,"*-> VIP Transferred") | D32: =COUNTIFS('_Import Seb ActivityLog'!$A$1:$A$5000,">="&(TODAY()-WEEKDAY(TODAY(),3)),'_Import Seb ActivityLog'!$A$1:$A$5000,"<="&TODAY(),'_Import Seb ActivityLog'!$C$1:$C$5000,"*-> First Deposit") | E32: =COUNTIFS('_Import Seb Book'!$H$1:$H$200,">="&DATE(YEAR(TODAY()),MONTH(TODAY()),1),'_Import Seb Book'!$H$1:$H$200,"<="&TODAY(),'_Import Seb Book'!$E$1:$E$200,"<>Dead Lead",'_Import Seb Book'!$E$1:$E$200,"<>Potential Lead") | F32: =COUNTIFS('_Import Seb ActivityLog'!$A$1:$A$5000,">="&DATE(YEAR(TODAY()),MONTH(TODAY()),1),'_Import Seb ActivityLog'!$A$1:$A$5000,"<="&TODAY(),'_Import Seb ActivityLog'!$C$1:$C$5000,"VIP Transfer")+COUNTIFS('_Import Seb ActivityLog'!$A$1:$A$5000,">="&DATE(YEAR(TODAY()),MONTH(TODAY()),1),'_Import Seb ActivityLog'!$A$1:$A$5000,"<="&TODAY(),'_Import Seb ActivityLog'!$C$1:$C$5000,"*-> VIP Transferred") | G32: =COUNTIFS('_Import Seb ActivityLog'!$A$1:$A$5000,">="&DATE(YEAR(TODAY()),MONTH(TODAY()),1),'_Import Seb ActivityLog'!$A$1:$A$5000,"<="&TODAY(),'_Import Seb ActivityLog'!$C$1:$C$5000,"*-> First Deposit")
A33: Pricey | B33: =COUNTIFS('_Import Pricey Book'!$H$1:$H$200,">="&(TODAY()-WEEKDAY(TODAY(),3)),'_Import Pricey Book'!$H$1:$H$200,"<="&TODAY(),'_Import Pricey Book'!$E$1:$E$200,"<>Dead Lead",'_Import Pricey Book'!$E$1:$E$200,"<>Potential Lead") | C33: =COUNTIFS('_Import Pricey ActivityLog'!$A$1:$A$5000,">="&(TODAY()-WEEKDAY(TODAY(),3)),'_Import Pricey ActivityLog'!$A$1:$A$5000,"<="&TODAY(),'_Import Pricey ActivityLog'!$C$1:$C$5000,"VIP Transfer")+COUNTIFS('_Import Pricey ActivityLog'!$A$1:$A$5000,">="&(TODAY()-WEEKDAY(TODAY(),3)),'_Import Pricey ActivityLog'!$A$1:$A$5000,"<="&TODAY(),'_Import Pricey ActivityLog'!$C$1:$C$5000,"*-> VIP Transferred") | D33: =COUNTIFS('_Import Pricey ActivityLog'!$A$1:$A$5000,">="&(TODAY()-WEEKDAY(TODAY(),3)),'_Import Pricey ActivityLog'!$A$1:$A$5000,"<="&TODAY(),'_Import Pricey ActivityLog'!$C$1:$C$5000,"*-> First Deposit") | E33: =COUNTIFS('_Import Pricey Book'!$H$1:$H$200,">="&DATE(YEAR(TODAY()),MONTH(TODAY()),1),'_Import Pricey Book'!$H$1:$H$200,"<="&TODAY(),'_Import Pricey Book'!$E$1:$E$200,"<>Dead Lead",'_Import Pricey Book'!$E$1:$E$200,"<>Potential Lead") | F33: =COUNTIFS('_Import Pricey ActivityLog'!$A$1:$A$5000,">="&DATE(YEAR(TODAY()),MONTH(TODAY()),1),'_Import Pricey ActivityLog'!$A$1:$A$5000,"<="&TODAY(),'_Import Pricey ActivityLog'!$C$1:$C$5000,"VIP Transfer")+COUNTIFS('_Import Pricey ActivityLog'!$A$1:$A$5000,">="&DATE(YEAR(TODAY()),MONTH(TODAY()),1),'_Import Pricey ActivityLog'!$A$1:$A$5000,"<="&TODAY(),'_Import Pricey ActivityLog'!$C$1:$C$5000,"*-> VIP Transferred") | G33: =COUNTIFS('_Import Pricey ActivityLog'!$A$1:$A$5000,">="&DATE(YEAR(TODAY()),MONTH(TODAY()),1),'_Import Pricey ActivityLog'!$A$1:$A$5000,"<="&TODAY(),'_Import Pricey ActivityLog'!$C$1:$C$5000,"*-> First Deposit")
A34: Seanok | B34: =COUNTIFS('_Import Seanok Book'!$H$1:$H$200,">="&(TODAY()-WEEKDAY(TODAY(),3)),'_Import Seanok Book'!$H$1:$H$200,"<="&TODAY(),'_Import Seanok Book'!$E$1:$E$200,"<>Dead Lead",'_Import Seanok Book'!$E$1:$E$200,"<>Potential Lead") | C34: =COUNTIFS('_Import Seanok ActivityLog'!$A$1:$A$5000,">="&(TODAY()-WEEKDAY(TODAY(),3)),'_Import Seanok ActivityLog'!$A$1:$A$5000,"<="&TODAY(),'_Import Seanok ActivityLog'!$C$1:$C$5000,"VIP Transfer")+COUNTIFS('_Import Seanok ActivityLog'!$A$1:$A$5000,">="&(TODAY()-WEEKDAY(TODAY(),3)),'_Import Seanok ActivityLog'!$A$1:$A$5000,"<="&TODAY(),'_Import Seanok ActivityLog'!$C$1:$C$5000,"*-> VIP Transferred") | D34: =COUNTIFS('_Import Seanok ActivityLog'!$A$1:$A$5000,">="&(TODAY()-WEEKDAY(TODAY(),3)),'_Import Seanok ActivityLog'!$A$1:$A$5000,"<="&TODAY(),'_Import Seanok ActivityLog'!$C$1:$C$5000,"*-> First Deposit") | E34: =COUNTIFS('_Import Seanok Book'!$H$1:$H$200,">="&DATE(YEAR(TODAY()),MONTH(TODAY()),1),'_Import Seanok Book'!$H$1:$H$200,"<="&TODAY(),'_Import Seanok Book'!$E$1:$E$200,"<>Dead Lead",'_Import Seanok Book'!$E$1:$E$200,"<>Potential Lead") | F34: =COUNTIFS('_Import Seanok ActivityLog'!$A$1:$A$5000,">="&DATE(YEAR(TODAY()),MONTH(TODAY()),1),'_Import Seanok ActivityLog'!$A$1:$A$5000,"<="&TODAY(),'_Import Seanok ActivityLog'!$C$1:$C$5000,"VIP Transfer")+COUNTIFS('_Import Seanok ActivityLog'!$A$1:$A$5000,">="&DATE(YEAR(TODAY()),MONTH(TODAY()),1),'_Import Seanok ActivityLog'!$A$1:$A$5000,"<="&TODAY(),'_Import Seanok ActivityLog'!$C$1:$C$5000,"*-> VIP Transferred") | G34: =COUNTIFS('_Import Seanok ActivityLog'!$A$1:$A$5000,">="&DATE(YEAR(TODAY()),MONTH(TODAY()),1),'_Import Seanok ActivityLog'!$A$1:$A$5000,"<="&TODAY(),'_Import Seanok ActivityLog'!$C$1:$C$5000,"*-> First Deposit")
A35: Gwen | B35: =COUNTIFS('_Import Gwen Book'!$H$1:$H$200,">="&(TODAY()-WEEKDAY(TODAY(),3)),'_Import Gwen Book'!$H$1:$H$200,"<="&TODAY(),'_Import Gwen Book'!$E$1:$E$200,"<>Dead Lead",'_Import Gwen Book'!$E$1:$E$200,"<>Potential Lead") | C35: =COUNTIFS('_Import Gwen ActivityLog'!$A$1:$A$5000,">="&(TODAY()-WEEKDAY(TODAY(),3)),'_Import Gwen ActivityLog'!$A$1:$A$5000,"<="&TODAY(),'_Import Gwen ActivityLog'!$C$1:$C$5000,"VIP Transfer")+COUNTIFS('_Import Gwen ActivityLog'!$A$1:$A$5000,">="&(TODAY()-WEEKDAY(TODAY(),3)),'_Import Gwen ActivityLog'!$A$1:$A$5000,"<="&TODAY(),'_Import Gwen ActivityLog'!$C$1:$C$5000,"*-> VIP Transferred") | D35: =COUNTIFS('_Import Gwen ActivityLog'!$A$1:$A$5000,">="&(TODAY()-WEEKDAY(TODAY(),3)),'_Import Gwen ActivityLog'!$A$1:$A$5000,"<="&TODAY(),'_Import Gwen ActivityLog'!$C$1:$C$5000,"*-> First Deposit") | E35: =COUNTIFS('_Import Gwen Book'!$H$1:$H$200,">="&DATE(YEAR(TODAY()),MONTH(TODAY()),1),'_Import Gwen Book'!$H$1:$H$200,"<="&TODAY(),'_Import Gwen Book'!$E$1:$E$200,"<>Dead Lead",'_Import Gwen Book'!$E$1:$E$200,"<>Potential Lead") | F35: =COUNTIFS('_Import Gwen ActivityLog'!$A$1:$A$5000,">="&DATE(YEAR(TODAY()),MONTH(TODAY()),1),'_Import Gwen ActivityLog'!$A$1:$A$5000,"<="&TODAY(),'_Import Gwen ActivityLog'!$C$1:$C$5000,"VIP Transfer")+COUNTIFS('_Import Gwen ActivityLog'!$A$1:$A$5000,">="&DATE(YEAR(TODAY()),MONTH(TODAY()),1),'_Import Gwen ActivityLog'!$A$1:$A$5000,"<="&TODAY(),'_Import Gwen ActivityLog'!$C$1:$C$5000,"*-> VIP Transferred") | G35: =COUNTIFS('_Import Gwen ActivityLog'!$A$1:$A$5000,">="&DATE(YEAR(TODAY()),MONTH(TODAY()),1),'_Import Gwen ActivityLog'!$A$1:$A$5000,"<="&TODAY(),'_Import Gwen ActivityLog'!$C$1:$C$5000,"*-> First Deposit")
A36: Miko | B36: =COUNTIFS('_Import Miko Book'!$H$1:$H$200,">="&(TODAY()-WEEKDAY(TODAY(),3)),'_Import Miko Book'!$H$1:$H$200,"<="&TODAY(),'_Import Miko Book'!$E$1:$E$200,"<>Dead Lead",'_Import Miko Book'!$E$1:$E$200,"<>Potential Lead") | C36: =COUNTIFS('_Import Miko ActivityLog'!$A$1:$A$5000,">="&(TODAY()-WEEKDAY(TODAY(),3)),'_Import Miko ActivityLog'!$A$1:$A$5000,"<="&TODAY(),'_Import Miko ActivityLog'!$C$1:$C$5000,"VIP Transfer")+COUNTIFS('_Import Miko ActivityLog'!$A$1:$A$5000,">="&(TODAY()-WEEKDAY(TODAY(),3)),'_Import Miko ActivityLog'!$A$1:$A$5000,"<="&TODAY(),'_Import Miko ActivityLog'!$C$1:$C$5000,"*-> VIP Transferred") | D36: =COUNTIFS('_Import Miko ActivityLog'!$A$1:$A$5000,">="&(TODAY()-WEEKDAY(TODAY(),3)),'_Import Miko ActivityLog'!$A$1:$A$5000,"<="&TODAY(),'_Import Miko ActivityLog'!$C$1:$C$5000,"*-> First Deposit") | E36: =COUNTIFS('_Import Miko Book'!$H$1:$H$200,">="&DATE(YEAR(TODAY()),MONTH(TODAY()),1),'_Import Miko Book'!$H$1:$H$200,"<="&TODAY(),'_Import Miko Book'!$E$1:$E$200,"<>Dead Lead",'_Import Miko Book'!$E$1:$E$200,"<>Potential Lead") | F36: =COUNTIFS('_Import Miko ActivityLog'!$A$1:$A$5000,">="&DATE(YEAR(TODAY()),MONTH(TODAY()),1),'_Import Miko ActivityLog'!$A$1:$A$5000,"<="&TODAY(),'_Import Miko ActivityLog'!$C$1:$C$5000,"VIP Transfer")+COUNTIFS('_Import Miko ActivityLog'!$A$1:$A$5000,">="&DATE(YEAR(TODAY()),MONTH(TODAY()),1),'_Import Miko ActivityLog'!$A$1:$A$5000,"<="&TODAY(),'_Import Miko ActivityLog'!$C$1:$C$5000,"*-> VIP Transferred") | G36: =COUNTIFS('_Import Miko ActivityLog'!$A$1:$A$5000,">="&DATE(YEAR(TODAY()),MONTH(TODAY()),1),'_Import Miko ActivityLog'!$A$1:$A$5000,"<="&TODAY(),'_Import Miko ActivityLog'!$C$1:$C$5000,"*-> First Deposit")
A37: Concept | B37: =COUNTIFS('_Import Concept Book'!$H$1:$H$200,">="&(TODAY()-WEEKDAY(TODAY(),3)),'_Import Concept Book'!$H$1:$H$200,"<="&TODAY(),'_Import Concept Book'!$E$1:$E$200,"<>Dead Lead",'_Import Concept Book'!$E$1:$E$200,"<>Potential Lead") | C37: =COUNTIFS('_Import Concept ActivityLog'!$A$1:$A$5000,">="&(TODAY()-WEEKDAY(TODAY(),3)),'_Import Concept ActivityLog'!$A$1:$A$5000,"<="&TODAY(),'_Import Concept ActivityLog'!$C$1:$C$5000,"VIP Transfer")+COUNTIFS('_Import Concept ActivityLog'!$A$1:$A$5000,">="&(TODAY()-WEEKDAY(TODAY(),3)),'_Import Concept ActivityLog'!$A$1:$A$5000,"<="&TODAY(),'_Import Concept ActivityLog'!$C$1:$C$5000,"*-> VIP Transferred") | D37: =COUNTIFS('_Import Concept ActivityLog'!$A$1:$A$5000,">="&(TODAY()-WEEKDAY(TODAY(),3)),'_Import Concept ActivityLog'!$A$1:$A$5000,"<="&TODAY(),'_Import Concept ActivityLog'!$C$1:$C$5000,"*-> First Deposit") | E37: =COUNTIFS('_Import Concept Book'!$H$1:$H$200,">="&DATE(YEAR(TODAY()),MONTH(TODAY()),1),'_Import Concept Book'!$H$1:$H$200,"<="&TODAY(),'_Import Concept Book'!$E$1:$E$200,"<>Dead Lead",'_Import Concept Book'!$E$1:$E$200,"<>Potential Lead") | F37: =COUNTIFS('_Import Concept ActivityLog'!$A$1:$A$5000,">="&DATE(YEAR(TODAY()),MONTH(TODAY()),1),'_Import Concept ActivityLog'!$A$1:$A$5000,"<="&TODAY(),'_Import Concept ActivityLog'!$C$1:$C$5000,"VIP Transfer")+COUNTIFS('_Import Concept ActivityLog'!$A$1:$A$5000,">="&DATE(YEAR(TODAY()),MONTH(TODAY()),1),'_Import Concept ActivityLog'!$A$1:$A$5000,"<="&TODAY(),'_Import Concept ActivityLog'!$C$1:$C$5000,"*-> VIP Transferred") | G37: =COUNTIFS('_Import Concept ActivityLog'!$A$1:$A$5000,">="&DATE(YEAR(TODAY()),MONTH(TODAY()),1),'_Import Concept ActivityLog'!$A$1:$A$5000,"<="&TODAY(),'_Import Concept ActivityLog'!$C$1:$C$5000,"*-> First Deposit")
A38: Daily | B38: =COUNTIFS('_Import Daily Book'!$H$1:$H$200,">="&(TODAY()-WEEKDAY(TODAY(),3)),'_Import Daily Book'!$H$1:$H$200,"<="&TODAY(),'_Import Daily Book'!$E$1:$E$200,"<>Dead Lead",'_Import Daily Book'!$E$1:$E$200,"<>Potential Lead") | C38: =COUNTIFS('_Import Daily ActivityLog'!$A$1:$A$5000,">="&(TODAY()-WEEKDAY(TODAY(),3)),'_Import Daily ActivityLog'!$A$1:$A$5000,"<="&TODAY(),'_Import Daily ActivityLog'!$C$1:$C$5000,"VIP Transfer")+COUNTIFS('_Import Daily ActivityLog'!$A$1:$A$5000,">="&(TODAY()-WEEKDAY(TODAY(),3)),'_Import Daily ActivityLog'!$A$1:$A$5000,"<="&TODAY(),'_Import Daily ActivityLog'!$C$1:$C$5000,"*-> VIP Transferred") | D38: =COUNTIFS('_Import Daily ActivityLog'!$A$1:$A$5000,">="&(TODAY()-WEEKDAY(TODAY(),3)),'_Import Daily ActivityLog'!$A$1:$A$5000,"<="&TODAY(),'_Import Daily ActivityLog'!$C$1:$C$5000,"*-> First Deposit") | E38: =COUNTIFS('_Import Daily Book'!$H$1:$H$200,">="&DATE(YEAR(TODAY()),MONTH(TODAY()),1),'_Import Daily Book'!$H$1:$H$200,"<="&TODAY(),'_Import Daily Book'!$E$1:$E$200,"<>Dead Lead",'_Import Daily Book'!$E$1:$E$200,"<>Potential Lead") | F38: =COUNTIFS('_Import Daily ActivityLog'!$A$1:$A$5000,">="&DATE(YEAR(TODAY()),MONTH(TODAY()),1),'_Import Daily ActivityLog'!$A$1:$A$5000,"<="&TODAY(),'_Import Daily ActivityLog'!$C$1:$C$5000,"VIP Transfer")+COUNTIFS('_Import Daily ActivityLog'!$A$1:$A$5000,">="&DATE(YEAR(TODAY()),MONTH(TODAY()),1),'_Import Daily ActivityLog'!$A$1:$A$5000,"<="&TODAY(),'_Import Daily ActivityLog'!$C$1:$C$5000,"*-> VIP Transferred") | G38: =COUNTIFS('_Import Daily ActivityLog'!$A$1:$A$5000,">="&DATE(YEAR(TODAY()),MONTH(TODAY()),1),'_Import Daily ActivityLog'!$A$1:$A$5000,"<="&TODAY(),'_Import Daily ActivityLog'!$C$1:$C$5000,"*-> First Deposit")
A39: Prime | B39: =COUNTIFS('_Import Prime Book'!$H$1:$H$200,">="&(TODAY()-WEEKDAY(TODAY(),3)),'_Import Prime Book'!$H$1:$H$200,"<="&TODAY(),'_Import Prime Book'!$E$1:$E$200,"<>Dead Lead",'_Import Prime Book'!$E$1:$E$200,"<>Potential Lead") | C39: =COUNTIFS('_Import Prime ActivityLog'!$A$1:$A$5000,">="&(TODAY()-WEEKDAY(TODAY(),3)),'_Import Prime ActivityLog'!$A$1:$A$5000,"<="&TODAY(),'_Import Prime ActivityLog'!$C$1:$C$5000,"VIP Transfer")+COUNTIFS('_Import Prime ActivityLog'!$A$1:$A$5000,">="&(TODAY()-WEEKDAY(TODAY(),3)),'_Import Prime ActivityLog'!$A$1:$A$5000,"<="&TODAY(),'_Import Prime ActivityLog'!$C$1:$C$5000,"*-> VIP Transferred") | D39: =COUNTIFS('_Import Prime ActivityLog'!$A$1:$A$5000,">="&(TODAY()-WEEKDAY(TODAY(),3)),'_Import Prime ActivityLog'!$A$1:$A$5000,"<="&TODAY(),'_Import Prime ActivityLog'!$C$1:$C$5000,"*-> First Deposit") | E39: =COUNTIFS('_Import Prime Book'!$H$1:$H$200,">="&DATE(YEAR(TODAY()),MONTH(TODAY()),1),'_Import Prime Book'!$H$1:$H$200,"<="&TODAY(),'_Import Prime Book'!$E$1:$E$200,"<>Dead Lead",'_Import Prime Book'!$E$1:$E$200,"<>Potential Lead") | F39: =COUNTIFS('_Import Prime ActivityLog'!$A$1:$A$5000,">="&DATE(YEAR(TODAY()),MONTH(TODAY()),1),'_Import Prime ActivityLog'!$A$1:$A$5000,"<="&TODAY(),'_Import Prime ActivityLog'!$C$1:$C$5000,"VIP Transfer")+COUNTIFS('_Import Prime ActivityLog'!$A$1:$A$5000,">="&DATE(YEAR(TODAY()),MONTH(TODAY()),1),'_Import Prime ActivityLog'!$A$1:$A$5000,"<="&TODAY(),'_Import Prime ActivityLog'!$C$1:$C$5000,"*-> VIP Transferred") | G39: =COUNTIFS('_Import Prime ActivityLog'!$A$1:$A$5000,">="&DATE(YEAR(TODAY()),MONTH(TODAY()),1),'_Import Prime ActivityLog'!$A$1:$A$5000,"<="&TODAY(),'_Import Prime ActivityLog'!$C$1:$C$5000,"*-> First Deposit")
A40: Yuri | B40: =COUNTIFS('_Import Yuri Book'!$H$1:$H$200,">="&(TODAY()-WEEKDAY(TODAY(),3)),'_Import Yuri Book'!$H$1:$H$200,"<="&TODAY(),'_Import Yuri Book'!$E$1:$E$200,"<>Dead Lead",'_Import Yuri Book'!$E$1:$E$200,"<>Potential Lead") | C40: =COUNTIFS('_Import Yuri ActivityLog'!$A$1:$A$5000,">="&(TODAY()-WEEKDAY(TODAY(),3)),'_Import Yuri ActivityLog'!$A$1:$A$5000,"<="&TODAY(),'_Import Yuri ActivityLog'!$C$1:$C$5000,"VIP Transfer")+COUNTIFS('_Import Yuri ActivityLog'!$A$1:$A$5000,">="&(TODAY()-WEEKDAY(TODAY(),3)),'_Import Yuri ActivityLog'!$A$1:$A$5000,"<="&TODAY(),'_Import Yuri ActivityLog'!$C$1:$C$5000,"*-> VIP Transferred") | D40: =COUNTIFS('_Import Yuri ActivityLog'!$A$1:$A$5000,">="&(TODAY()-WEEKDAY(TODAY(),3)),'_Import Yuri ActivityLog'!$A$1:$A$5000,"<="&TODAY(),'_Import Yuri ActivityLog'!$C$1:$C$5000,"*-> First Deposit") | E40: =COUNTIFS('_Import Yuri Book'!$H$1:$H$200,">="&DATE(YEAR(TODAY()),MONTH(TODAY()),1),'_Import Yuri Book'!$H$1:$H$200,"<="&TODAY(),'_Import Yuri Book'!$E$1:$E$200,"<>Dead Lead",'_Import Yuri Book'!$E$1:$E$200,"<>Potential Lead") | F40: =COUNTIFS('_Import Yuri ActivityLog'!$A$1:$A$5000,">="&DATE(YEAR(TODAY()),MONTH(TODAY()),1),'_Import Yuri ActivityLog'!$A$1:$A$5000,"<="&TODAY(),'_Import Yuri ActivityLog'!$C$1:$C$5000,"VIP Transfer")+COUNTIFS('_Import Yuri ActivityLog'!$A$1:$A$5000,">="&DATE(YEAR(TODAY()),MONTH(TODAY()),1),'_Import Yuri ActivityLog'!$A$1:$A$5000,"<="&TODAY(),'_Import Yuri ActivityLog'!$C$1:$C$5000,"*-> VIP Transferred") | G40: =COUNTIFS('_Import Yuri ActivityLog'!$A$1:$A$5000,">="&DATE(YEAR(TODAY()),MONTH(TODAY()),1),'_Import Yuri ActivityLog'!$A$1:$A$5000,"<="&TODAY(),'_Import Yuri ActivityLog'!$C$1:$C$5000,"*-> First Deposit")

Sheet Team & KPI Targets
A1: Team Roster & Daily KPI Targets — All Reps
A2: Pulled live from each rep's own Team & KPI Targets tab (personal to them). To change a target, edit it on that rep's own file - it updates here automatically.
A4: Name | B4: Role | C4: Platforms | D4: Daily Outreach (static, not tracked) | E4: Active Leads Target (must log) | F4: VIP Transfers Target | G4: Daily FTD Target
A5: =IFERROR('_Import Tuna KPI'!A1,"") | B5: =IFERROR('_Import Tuna KPI'!B1,"") | C5: =IFERROR('_Import Tuna KPI'!C1,"") | D5: =IFERROR('_Import Tuna KPI'!D1,"") | E5: =IFERROR('_Import Tuna KPI'!E1,"") | F5: =IFERROR('_Import Tuna KPI'!F1,"") | G5: =IFERROR('_Import Tuna KPI'!G1,"")
A6: =IFERROR('_Import Plat KPI'!A1,"") | B6: =IFERROR('_Import Plat KPI'!B1,"") | C6: =IFERROR('_Import Plat KPI'!C1,"") | D6: =IFERROR('_Import Plat KPI'!D1,"") | E6: =IFERROR('_Import Plat KPI'!E1,"") | F6: =IFERROR('_Import Plat KPI'!F1,"") | G6: =IFERROR('_Import Plat KPI'!G1,"")
A7: =IFERROR('_Import Chella KPI'!A1,"") | B7: =IFERROR('_Import Chella KPI'!B1,"") | C7: =IFERROR('_Import Chella KPI'!C1,"") | D7: =IFERROR('_Import Chella KPI'!D1,"") | E7: =IFERROR('_Import Chella KPI'!E1,"") | F7: =IFERROR('_Import Chella KPI'!F1,"") | G7: =IFERROR('_Import Chella KPI'!G1,"")
A8: =IFERROR('_Import Moneyheist KPI'!A1,"") | B8: =IFERROR('_Import Moneyheist KPI'!B1,"") | C8: =IFERROR('_Import Moneyheist KPI'!C1,"") | D8: =IFERROR('_Import Moneyheist KPI'!D1,"") | E8: =IFERROR('_Import Moneyheist KPI'!E1,"") | F8: =IFERROR('_Import Moneyheist KPI'!F1,"") | G8: =IFERROR('_Import Moneyheist KPI'!G1,"")
A9: =IFERROR('_Import Seb KPI'!A1,"") | B9: =IFERROR('_Import Seb KPI'!B1,"") | C9: =IFERROR('_Import Seb KPI'!C1,"") | D9: =IFERROR('_Import Seb KPI'!D1,"") | E9: =IFERROR('_Import Seb KPI'!E1,"") | F9: =IFERROR('_Import Seb KPI'!F1,"") | G9: =IFERROR('_Import Seb KPI'!G1,"")
A10: =IFERROR('_Import Pricey KPI'!A1,"") | B10: =IFERROR('_Import Pricey KPI'!B1,"") | C10: =IFERROR('_Import Pricey KPI'!C1,"") | D10: =IFERROR('_Import Pricey KPI'!D1,"") | E10: =IFERROR('_Import Pricey KPI'!E1,"") | F10: =IFERROR('_Import Pricey KPI'!F1,"") | G10: =IFERROR('_Import Pricey KPI'!G1,"")
A11: =IFERROR('_Import Seanok KPI'!A1,"") | B11: =IFERROR('_Import Seanok KPI'!B1,"") | C11: =IFERROR('_Import Seanok KPI'!C1,"") | D11: =IFERROR('_Import Seanok KPI'!D1,"") | E11: =IFERROR('_Import Seanok KPI'!E1,"") | F11: =IFERROR('_Import Seanok KPI'!F1,"") | G11: =IFERROR('_Import Seanok KPI'!G1,"")
A12: =IFERROR('_Import Gwen KPI'!A1,"") | B12: =IFERROR('_Import Gwen KPI'!B1,"") | C12: =IFERROR('_Import Gwen KPI'!C1,"") | D12: =IFERROR('_Import Gwen KPI'!D1,"") | E12: =IFERROR('_Import Gwen KPI'!E1,"") | F12: =IFERROR('_Import Gwen KPI'!F1,"") | G12: =IFERROR('_Import Gwen KPI'!G1,"")
A13: =IFERROR('_Import Miko KPI'!A1,"") | B13: =IFERROR('_Import Miko KPI'!B1,"") | C13: =IFERROR('_Import Miko KPI'!C1,"") | D13: =IFERROR('_Import Miko KPI'!D1,"") | E13: =IFERROR('_Import Miko KPI'!E1,"") | F13: =IFERROR('_Import Miko KPI'!F1,"") | G13: =IFERROR('_Import Miko KPI'!G1,"")
A14: =IFERROR('_Import Concept KPI'!A1,"") | B14: =IFERROR('_Import Concept KPI'!B1,"") | C14: =IFERROR('_Import Concept KPI'!C1,"") | D14: =IFERROR('_Import Concept KPI'!D1,"") | E14: =IFERROR('_Import Concept KPI'!E1,"") | F14: =IFERROR('_Import Concept KPI'!F1,"") | G14: =IFERROR('_Import Concept KPI'!G1,"")
A15: =IFERROR('_Import Daily KPI'!A1,"") | B15: =IFERROR('_Import Daily KPI'!B1,"") | C15: =IFERROR('_Import Daily KPI'!C1,"") | D15: =IFERROR('_Import Daily KPI'!D1,"") | E15: =IFERROR('_Import Daily KPI'!E1,"") | F15: =IFERROR('_Import Daily KPI'!F1,"") | G15: =IFERROR('_Import Daily KPI'!G1,"")
A16: =IFERROR('_Import Prime KPI'!A1,"") | B16: =IFERROR('_Import Prime KPI'!B1,"") | C16: =IFERROR('_Import Prime KPI'!C1,"") | D16: =IFERROR('_Import Prime KPI'!D1,"") | E16: =IFERROR('_Import Prime KPI'!E1,"") | F16: =IFERROR('_Import Prime KPI'!F1,"") | G16: =IFERROR('_Import Prime KPI'!G1,"")
A17: =IFERROR('_Import Yuri KPI'!A1,"") | B17: =IFERROR('_Import Yuri KPI'!B1,"") | C17: =IFERROR('_Import Yuri KPI'!C1,"") | D17: =IFERROR('_Import Yuri KPI'!D1,"") | E17: =IFERROR('_Import Yuri KPI'!E1,"") | F17: =IFERROR('_Import Yuri KPI'!F1,"") | G17: =IFERROR('_Import Yuri KPI'!G1,"")

Sheet _Import Tuna Book
A1: =IMPORTRANGE("1E2DMtbb0qnQMj6PLoA3xPq59m3Gt0vnJl7UopBaMqhc", "'Tuna - Book'!A4:O203")

Sheet _Import Tuna ActivityLog
A1: =IMPORTRANGE("1E2DMtbb0qnQMj6PLoA3xPq59m3Gt0vnJl7UopBaMqhc", "'Tuna - Activity Log'!A5:E5004")

Sheet _Import Tuna VIPTeam
